Workbook
Name _Hlk152162896: '指定共同生活援助（共通）'!$B$67
Name _Hlk152264793: '指定共同生活援助（共通）'!$B$70
Name _Hlk152162896: '指定共同生活援助（日中サービス支援型）'!#REF!
Name _Hlk152264793: '指定共同生活援助（日中サービス支援型）'!#REF!
Name _Hlk152162896: '指定共同生活援助（外部サービス利用型）'!#REF!
Name _Hlk152264793: '指定共同生活援助（外部サービス利用型）'!#REF!
Name _Hlk152162896: '指定共同生活援助（訓練等給付費の算定）'!#REF!
Name _Hlk152264793: '指定共同生活援助（訓練等給付費の算定）'!#REF!

Sheet 要確認一覧
A1: シート名 | B1: 確認項目（大区分） | C1: 確認事項（抜粋） | D1: 判定
A2: 指定共同生活援助（共通） | B2: （指定障害福祉サービス事業者の一般原則） | C2: （１）指定共同生活援助事業者は、利用者の意向、適性、障害の特性その他の事情を踏まえた計画（個別支援計画）を作成し、これに基づき利用者に対して指定共同生活援助を提 | D2: ='指定共同生活援助（共通）'!G5
A3: 指定共同生活援助（共通） | C3: （２）指定共同生活援助事業者は、利用者の意思及び人格を尊重して、常に当該利用者の立場に立った指定共同生活援助の提供に努めているか。 | D3: ='指定共同生活援助（共通）'!G6
A4: 指定共同生活援助（共通） | C4: （３）指定共同生活援助事業者は、利用者の人権の擁護、虐待の防止等のため、必要な体制の整備を行うとともに、その従業者に対し、研修を実施する等の措置を講じているか。 | D4: ='指定共同生活援助（共通）'!G7
A5: 指定共同生活援助（共通） | C5: （４）指定共同生活援助の事業は、利用者が地域において共同して自立した日常生活又は社会生活を営むことができるよう、当該利用者の身体及び精神の状況並びにその置かれて | D5: ='指定共同生活援助（共通）'!G8
A6: 指定共同生活援助（共通） | B6: １ 指定共同生活援助事業所の従業者の員数 | C6: 指定共同生活援助事業所に置くべき従業者及びその員数は、次のとおりになっているか。 | D6: ='指定共同生活援助（共通）'!G11
A7: 指定共同生活援助（共通） | B7: （１）世話人 | C7: 指定共同生活援助事業所ごとに、常勤換算方法で、利用者の数を6で除した数以上となっているか。 | D7: ='指定共同生活援助（共通）'!G12
A8: 指定共同生活援助（共通） | B8: （２）生活支援員 | C8: 指定共同生活援助事業所ごとに、常勤換算方法で、次の①から④までに掲げる数の合計数以上となっているか。 ① 障害支援区分に係る市町村審査会による審査及び判定の基準 | D8: ='指定共同生活援助（共通）'!G13
A9: 指定共同生活援助（共通） | B9: （３）サービス管理責任者 | C9: 指定共同生活援助事業所ごとに、①又は②に掲げる利用者の数の区分に応じ、それぞれ①又は②に掲げる数となっているか。 ① 利用者の数が30以下 1以上 ② 利用者の | D9: ='指定共同生活援助（共通）'!G14
A10: 指定共同生活援助（共通） | B10: （４）利用者数の算定 | C10: (1)から(3)の利用者の数は、前年度の平均値となっているか。ただし、新規に指定を受ける場合は、適切な推定数により算定されているか。 | D10: ='指定共同生活援助（共通）'!G15
A11: 指定共同生活援助（共通） | B11: （５）職務の専従 | C11: (1)から(3)に規定する指定共同生活援助の従業者は､専ら当該指定共同生活援助事業所の職務に従事する者となっているか。 （ただし、利用者の支援に支障がない場合は | D11: ='指定共同生活援助（共通）'!G16
A12: 指定共同生活援助（共通） | B12: （６）管理者 | C12: ① 指定共同生活援助事業所ごとに専らその職務に従事する常勤の管理者を置いているか。 （ただし、指定共同生活援助事業所の管理上支障がない場合は、当該指定共同生活援 | D12: ='指定共同生活援助（共通）'!G17
A13: 指定共同生活援助（共通） | C13: ② 指定共同生活援助事業所の管理者は、適切な指定共同生活援助を提供するために必要な知識及び経験を有する者となっているか。 | D13: ='指定共同生活援助（共通）'!G18
A14: 指定共同生活援助（共通） | B14: 設備 | C14: ① 指定共同生活援助に係る共同生活住居は、住宅地又は住宅地と同程度に利用者の家族や地域住民との交流の機会が確保される地域にあり、かつ、入所により日中及び夜間を通 | D14: ='指定共同生活援助（共通）'!G21
A15: 指定共同生活援助（共通） | C15: ② 指定共同生活援助事業所は、1以上の共同生活住居（サテライト型住居を除く。以下この②、④から⑥までにおいて同じ。）を有するものとし、当該共同生活住居及びサテラ | D15: ='指定共同生活援助（共通）'!G22
A16: 指定共同生活援助（共通） | C16: ③ 共同生活住居の配置、構造及び設備は、利用者の特性に応じて工夫したものとなっているか。 | D16: ='指定共同生活援助（共通）'!G23
A17: 指定共同生活援助（共通） | C17: ④ 共同生活住居は、その入居定員は2人以上10人以下となっているか。 ただし、既存の建物を共同生活住居とする場合にあっては、当該共同生活住居の入居定員は2人以 | D17: ='指定共同生活援助（共通）'!G24
A18: 指定共同生活援助（共通） | C18: ⑤ 既存の建物を共同生活住居とした共同生活住居を改築する場合であって、都道府県知事が特に必要があると認めるときは、④の規定にかかわらず、当該共同生活住居の入居定 | D18: ='指定共同生活援助（共通）'!G25
A19: 指定共同生活援助（共通） | C19: ⑥ 共同生活住居は、１以上のユニットを有するほか、日常生活を営む上で必要な設備を設けているか。 | D19: ='指定共同生活援助（共通）'!G26
A20: 指定共同生活援助（共通） | C20: ⑦ ユニットの入居定員は、2人以上10人以下となっているか。 | D20: ='指定共同生活援助（共通）'!G27
A21: 指定共同生活援助（共通） | C21: ⑧ ユニットには、居室及び居室に近接して設けられる相互に交流を図ることができる設備を設けているか。その基準は次のとおりとなっているか。 ア １の居室の定員は、１ | D21: ='指定共同生活援助（共通）'!G28
A22: 指定共同生活援助（共通） | C22: ⑨ サテライト型住居の基準は、次のとおりとなっているか。 ア 入居定員を１人とすること。 イ 日常生活を営む上で必要な設備を設けること。 ウ 居室の面積は、収 | D22: ='指定共同生活援助（共通）'!G29
A23: 指定共同生活援助（共通） | C23: （経過措置） （１）平成18年厚生労働省令第171号（指定障害福祉サービス基準）の施行日（施行日）において現に入所施設又は病院の敷地内に存する建物を共同生活住居 | D23: ='指定共同生活援助（共通）'!G30
A24: 指定共同生活援助（共通） | C24: （２）指定共同生活援助事業者は、施行日において現に存する指定共同生活援助事業所において、指定共同生活援助の事業を行う場合には、当該事業所の共同生活住居（基本的な | D24: ='指定共同生活援助（共通）'!G31
A25: 指定共同生活援助（共通） | C25: （３）施行日において現に存する身体障害者福祉ホーム、精神障害者生活訓練施設、指定知的障害者通勤寮若しくは知的障害者福祉ホーム又は旧精神障害者福祉ホ－ム（基本的な | D25: ='指定共同生活援助（共通）'!G32
A26: 指定共同生活援助（共通） | B26: １ 内容及び手続の説明及び同意 | C26: （１）指定共同生活援助事業者は、支給決定障害者等が指定共同生活援助の利用の申込みを行ったときは、当該利用申込者に係る障害の特性に応じた適切な配慮をしつつ、当該利 | D26: ='指定共同生活援助（共通）'!G35
A27: 指定共同生活援助（共通） | C27: （２）指定共同生活援助事業者は、社会福祉法第77条の規定に基づき書面の交付を行う場合は、利用者の障害の特性に応じた適切な配慮をしているか。 | D27: ='指定共同生活援助（共通）'!G36
A28: 指定共同生活援助（共通） | B28: ２ 提供拒否の禁止 | C28: 指定共同生活援助事業者は、正当な理由がなく、指定共同生活援助の提供を拒んでいないか。 | D28: ='指定共同生活援助（共通）'!G37
A29: 指定共同生活援助（共通） | B29: ３ 連絡調整に対する協力 | C29: 指定共同生活援助事業者は、指定共同生活援助の利用について市町村又は一般相談支援事業若しくは特定相談支援事業を行う者が行う連絡調整に、できる限り協力しているか。 | D29: ='指定共同生活援助（共通）'!G38
A30: 指定共同生活援助（共通） | B30: ４ 受給資格の確認 | C30: 指定共同生活援助事業者は、指定共同生活援助の提供を求められた場合は、その者の提示する受給者証によって、支給決定の有無、支給決定の有効期間、支給量等を確かめている | D30: ='指定共同生活援助（共通）'!G39
A31: 指定共同生活援助（共通） | B31: ５ 訓練等給付費の支給の申請に係る援助 | C31: （１）指定共同生活援助事業者は、共同生活援助に係る支給決定を受けていない者から利用の申込みがあった場合は、その者の意向を踏まえて速やかに訓練等給付費の支給の申請 | D31: ='指定共同生活援助（共通）'!G40
A32: 指定共同生活援助（共通） | C32: （２）指定共同生活援助事業者は、共同生活援助に係る支給決定に通常要すべき標準的な期間を考慮し、支給決定の有効期間の終了に伴う訓練等給付費の支給申請について、必要 | D32: ='指定共同生活援助（共通）'!G41
A33: 指定共同生活援助（共通） | B33: ６ 心身の状況等の把握 | C33: 指定共同生活援助事業者は、指定共同生活援助の提供に当たっては、利用者の心身の状況、その置かれている環境、他の保健医療サービス又は福祉サービスの利用状況等の把握に | D33: ='指定共同生活援助（共通）'!G42
A34: 指定共同生活援助（共通） | B34: ７ 指定障害福祉サービス事業者等との連携等 | C34: （１）指定共同生活援助事業者は、指定共同生活援助を提供するに当たっては、地域及び家庭との結び付きを重視した運営を行い、市町村、他の指定障害福祉サービス事業者等そ | D34: ='指定共同生活援助（共通）'!G43
A35: 指定共同生活援助（共通） | C35: （２）指定共同生活援助事業者は、指定共同生活援助の提供の終了に際しては、利用者又はその家族に対して適切な援助を行うとともに、保健医療サービス又は福祉サービスを提 | D35: ='指定共同生活援助（共通）'!G44
A36: 指定共同生活援助（共通） | B36: ８ サービスの提供の記録 | C36: （１）指定共同生活援助事業者は、指定共同生活援助を提供した際は、当該指定共同生活援助の提供日、内容その他必要な事項を記録しているか。 | D36: ='指定共同生活援助（共通）'!G45
A37: 指定共同生活援助（共通） | C37: （２）指定共同生活援助事業者は、(1)の規定による記録に際しては、支給決定障害者等から指定共同生活援助を提供したことについて確認を受けているか。 | D37: ='指定共同生活援助（共通）'!G46
A38: 指定共同生活援助（共通） | B38: ９ 入退居 | C38: （１）指定共同生活援助は、共同生活住居への入居を必要とする利用者(入院治療を要する者を除く。)に提供されているか。 | D38: ='指定共同生活援助（共通）'!G47
A39: 指定共同生活援助（共通） | C39: （２）指定共同生活援助事業者は、利用申込者の入居に際しては、その者の心身の状況、生活歴、病歴等の把握に努めているか。 | D39: ='指定共同生活援助（共通）'!G48
A40: 指定共同生活援助（共通） | C40: （３）指定共同生活援助事業者は、利用者の退居の際は、利用者の希望を踏まえた上で、退居後の生活環境や援助の継続性に配慮し、退居に必要な援助を行い、又はこれに併せて | D40: ='指定共同生活援助（共通）'!G49
...

Sheet 指定共同生活援助（共通）
C1: ※法：障害者総合支援法（障害者の日常生活及び社会生活を総合的に支援するための法律）
A2: （注）下線を付した項目が標準確認項目 | C2: ※平18厚令171：運営基準（障害者の日常生活及び社会生活を総合的に支援するための法律に基づく指定障害福祉サービスの事業等の人員、設備及び運営に関する基準）
A3: 確認項目 | B3: 確認事項 | C3: チェックポイント | D3: 根拠法令 | E3: 関係書類 | F3: 確認書類（１つ） | G3: 判定
A4: 第１基本方針 | D4: 法第43条
A5: （指定障害福祉サービス事業者の一般原則） | B5: （１）指定共同生活援助事業者は、利用者の意向、適性、障害の特性その他の事情を踏まえた計画（個別支援計画）を作成し、これに基づき利用者に対して指定共同生活援助を提供するとともに、その効果について継続的な評価を実施することその他の措置を講ずることにより利用者に対して適切かつ効果的に指定共同生活援助を提供しているか。 | C5: (1) 個別支援計画の作成と効果の評価 【現場でのチェックポイント】計画通りの支援と、定期的な振り返りができていますか？ ・適切な計画づくり： ご利用者の希望、得意なこと、障害の特性などをしっかり反映した「個別支援計画」を作成しているか。 ・計画に沿ったサポート： 作成した計画に基づき、日々の支援をブレずに提供できているか。 ・効果の確認と見直し： 支援の効果が本当に出ているかを定期的に振り返り（モニタリング）、必要に応じて計画や関わり方をアップデートしているか。 | D5: 平18厚令171 第3条第1項 | E5: 運営規程 個別支援計画 ケース記録
B6: （２）指定共同生活援助事業者は、利用者の意思及び人格を尊重して、常に当該利用者の立場に立った指定共同生活援助の提供に努めているか。 | C6: (2) ご利用者の意思・人格の尊重 【現場でのチェックポイント】常にご利用者ファーストの視点で、尊厳を大切にできていますか？ ・意思の尊重： ご利用者自身の「こうしたい」「こう生きたい」という思いや選択を尊重しているか。 ・ご利用者視点の徹底： スタッフの都合や施設のルールを押し付けるのではなく、常にご利用者の立場に立った丁寧な関わりを心がけているか。 | D6: 平18厚令171 第3条第2項 | E6: 運営規程 個別支援計画 ケース記録
B7: （３）指定共同生活援助事業者は、利用者の人権の擁護、虐待の防止等のため、必要な体制の整備を行うとともに、その従業者に対し、研修を実施する等の措置を講じているか。 | C7: (3) 人権の擁護・虐待の防止 【現場でのチェックポイント】虐待を防ぎ、人権を守るための体制づくりと研修ができていますか？ ・組織としての仕組み： 虐待防止責任者の配置や、マニュアル・通報窓口の整備など、不適切な関わりを絶対に生まないための体制を整えているか。 ・スタッフ教育の実施： 全スタッフを対象に、定期的な虐待防止研修や人権擁護に関する研修をしっかりと実施しているか。 | D7: 平18厚令171 第3条第3項 | E7: 運営規程 研修計画、研修実施記録 虐待防止関係書類 体制の整備をしていることが分かる書類
B8: （４）指定共同生活援助の事業は、利用者が地域において共同して自立した日常生活又は社会生活を営むことができるよう、当該利用者の身体及び精神の状況並びにその置かれている環境に応じて共同生活住居において相談、入浴、排せつ若しくは食事の介護その他の日常生活上の援助を適切かつ効果的に行い、又はこれに併せて、居宅における自立した日常生活への移行を希望する入居者につき当該日常生活への移行及び移行後の定着に関する相談、住居の確保に係る援助その他居宅における自立した日常生活への移行及び移行後の定着に必要な援助を適切かつ効果的に行っているか。 | C8: (4) 日常生活の援助と一人暮らし（居宅移行）への支援 【現場でのチェックポイント】ホームでの自立を支え、一人暮らしへのステップアップも応援できていますか？ ・日々の自立支援： ご利用者の心身の状況に合わせて、相談対応、入浴、排せつ、食事といった生活全般のサポートを適切に行い、地域での自立した暮らしを支えているか。 ・一人暮らしへの移行サポート： 将来的にアパートなどでの一人暮らし（居宅への移行）を希望するご利用者に対し、住まい探しの手伝いや、引っ越し後も地域生活に馴染めるような相談・見守り支援を適切に行っているか。 | D8: 平18厚令171 第207条 | E8: 運営規程 個別支援計画 ケース記録
A9: 確認項目 | B9: 確認事項 | C9: チェックポイント | D9: 根拠法令 | E9: 関係書類
A10: 第２ 人員に関す る基準 | D10: 法第43条第1項
A11: １ 指定共同生活援助事業所の従業者の員数 | B11: 指定共同生活援助事業所に置くべき従業者及びその員数は、次のとおりになっているか。 | C11: 1. スタッフ（世話人・生活支援員など）の配置人数 【現場でのチェック】ご利用者の人数や状況に対して、スタッフの「常勤換算（労働時間）」は足りていますか？ | D11: 平18厚令171 第208条第1項
A12: （１）世話人 | B12: 指定共同生活援助事業所ごとに、常勤換算方法で、利用者の数を6で除した数以上となっているか。 | C12: （1）基本の配置（世話人など）： ・全体のご利用者数を「6」で割った数以上のスタッフが配置されているか。 | D12: 平18厚令171 第208条第1項第1号 | E12: 勤務実績表 出勤簿（タイムカード） 従業員の資格証 勤務体制一覧表 利用者数（平均利用人数）が分かる書類（実績表等）
A13: （２）生活支援員 | B13: 指定共同生活援助事業所ごとに、常勤換算方法で、次の①から④までに掲げる数の合計数以上となっているか。 ① 障害支援区分に係る市町村審査会による審査及び判定の基準等に関する省令（平成26年厚生労働省令第5号）（区分省令）第1条第4号に規定する区分3に該当する利用者の数を9で除した数 ② 区分省令第1条第5号に規定する区分4に該当する利用者の数を6で除した数 ③ 区分省令第1条第6号に規定する区分5に該当する利用者の数を4で除した数 ④ 区分省令第1条第7号に規定する区分6に該当する利用者の数を2．5で除した数 | C13: （2）手厚いサポートが必要な方の配置（生活支援員など）： 以下の「区分ごとの計算」をすべて足した合計人数以上になっているか。 ・区分3のご利用者数 ÷ 9 ・区分4のご利用者数 ÷ 6 ・区分5のご利用者数 ÷ 4 ・区分6のご利用者数（※それぞれの基準に応じた数） | D13: 平18厚令171 第208条第1項 第2号 平26厚令5 第1条 | E13: 勤務実績表 出勤簿（タイムカード） 従業員の資格証 勤務体制一覧表 利用者数（平均利用人数）が分かる書類（実績表等）
A14: （３）サービス管理責任者 | B14: 指定共同生活援助事業所ごとに、①又は②に掲げる利用者の数の区分に応じ、それぞれ①又は②に掲げる数となっているか。 ① 利用者の数が30以下 1以上 ② 利用者の数が31以上 1に、利用者の数が30を超えて30又はその端数を増すごとに1を加えて得た数以上 | C14: （3） サービス管理責任者（サビ管）の配置 【現場でのチェック】ご利用者数に応じた人数のサビ管を配置できていますか？ ・ご利用者が30人以下： 1人以上の配置が必要です。 ・ご利用者が31人以上： 30人（またはその端数）が増えるごとに「+1人」を追加しているか。 【早見表】 ・1人〜30人：1人以上 ・31人〜60人：2人以上 ・61人〜90人：3人以上 | D14: 平18厚令171 第208条第1項第3号 | E14: 勤務実績表 出勤簿（タイムカード） 従業員の資格証 勤務体制一覧表 利用者数（平均利用人数）が分かる書類（実績表等）
A15: （４）利用者数の算定 | B15: (1)から(3)の利用者の数は、前年度の平均値となっているか。ただし、新規に指定を受ける場合は、適切な推定数により算定されているか。 | C15: （4）計算のベースにする「ご利用者数」のルール 【現場でのチェック】人数を計算するときの「ご利用者数」は正しい数字を使っていますか？ ・すでに対象の事業を行っている場合： 「前年度の平均ご利用者数」をベースに計算します。 ・新しくオープン（新規指定）する場合： 適切に見込んだ「推定のご利用者数」で計算して構いません。 | D15: 平18厚令171 第208条第2項 | E15: 利用者数（平均利用人数）が分かる書類（実績表等）
A16: （５）職務の専従 | B16: (1)から(3)に規定する指定共同生活援助の従業者は､専ら当該指定共同生活援助事業所の職務に従事する者となっているか。 （ただし、利用者の支援に支障がない場合はこの限りでない。） | C16: （5）管理者・スタッフの働き方（専従・兼務） 【現場でのチェック】管理者やスタッフの「兼務」のルールは守られていますか？ ・スタッフの原則： 基本的には、そのグループホームの仕事に専念しているか（ただし、ご利用者への支援に支障が出ない範囲であれば、例外も認められます）。 | D16: 平18厚令171 第208条第3項 | E16: 従業者の勤務実態の分かる書類 （出勤簿等）
A17: （６）管理者 | B17: ① 指定共同生活援助事業所ごとに専らその職務に従事する常勤の管理者を置いているか。 （ただし、指定共同生活援助事業所の管理上支障がない場合は、当該指定共同生活援助事業所の他の職務に従事させ、又は他の事業所、施設等の職務に従事させることができる。） | C17: ・管理者の配置： 常勤の管理者を1人、専従で置いているか。 ・管理者の兼務ルール： 管理業務に支障がない範囲であれば、同じホームの他の仕事（サビ管など）や、他の事業所の仕事を兼務しても問題ありません。 | D17: 平18厚令171 第209条第1項 | E17: 管理者の雇用形態が分かる書類 勤務実績表 出勤簿（タイムカード） 従業員の資格証 勤務体制一覧表
B18: ② 指定共同生活援助事業所の管理者は、適切な指定共同生活援助を提供するために必要な知識及び経験を有する者となっているか。 | C18: ・管理者の資質： グループホームを適切に運営するための「必要な知識や経験」を持っている人が管理者に就いているか。 | D18: 平18厚令171 第209条第2項 | E18: 管理者に必要な知識や経験があることが分かる書類（資格証、研修修了証
A19: 確認項目 | B19: 確認事項 | C19: チェックポイント | D19: 根拠法令 | E19: 関係書類
A20: 第３ 設備に関する基準 | D20: 法第43条第2項
A21: 設備 | B21: ① 指定共同生活援助に係る共同生活住居は、住宅地又は住宅地と同程度に利用者の家族や地域住民との交流の機会が確保される地域にあり、かつ、入所により日中及び夜間を通してサービスを提供する施設（入所施設）又は病院の敷地外にあるようになっているか。 | C21: ①ホームがある場所（立地）のルール 【現場でのチェック】地域から孤立せず、交流できる場所にありますか？・地域との交流ができる場所： ご利用者のご家族や地域住民の方々と、普段から自然に交流できるような住宅地（またはそれと同等の環境）に建っているか。 ・施設や病院の敷地外であること： 原則として、入所施設や病院の敷地内ではなく、一般的な地域の中に位置しているか。 | D21: 平18厚令171 第210条第1項 | E21: 平面図 【目視】
B22: ② 指定共同生活援助事業所は、1以上の共同生活住居（サテライト型住居を除く。以下この②、④から⑥までにおいて同じ。）を有するものとし、当該共同生活住居及びサテライト型住居の入居定員の合計は4人以上となっているか。 | C22: ②定員（人数）のルール 【現場でのチェック】事業所全体や、それぞれの住居の人数は適正ですか？ ・事業所全体の合計人数： 運営しているすべての住居（サテライト型を含む）の定員を足して、合計4人以上になっているか。 | D22: 平18厚令171 第210条第2項 | E22: 平面図 【目視】
B23: ③ 共同生活住居の配置、構造及び設備は、利用者の特性に応じて工夫したものとなっているか。 | C23: ③ご利用者に合わせた工夫： 建物の配置や設備が、ご利用者の障害の特性や状況に合わせて工夫されているか。 | D23: 平18厚令171 第210条第3項 | E23: 平面図 設備・備品等一覧表 【目視】
B24: ④ 共同生活住居は、その入居定員は2人以上10人以下となっているか。 ただし、既存の建物を共同生活住居とする場合にあっては、当該共同生活住居の入居定員は2人以上20人（都道府県知事（指定都市及び中核市にあっては、指定都市又は中核市の市長）が特に必要があると認めるときは30人）以下となっているか。 | C24: ④1つの住居の定員（原則）： 基本は2人以上 10人以下になっているか。 | D24: 平18厚令171 第210条第4項 | E24: 平面図 【目視】
B25: ⑤ 既存の建物を共同生活住居とした共同生活住居を改築する場合であって、都道府県知事が特に必要があると認めるときは、④の規定にかかわらず、当該共同生活住居の入居定員は2人以上30人以下（ただし、当該共同生活住居を改築する時点の入居定員と同数を上限とする。）となっているか。 | C25: ⑤既存の建物を活用・改築する場合： 自治体が特に認めれば、20人以下（特別な場合は30人以下）まで定員を広げることが可能です。 | D25: 平18厚令171 第210条第5項 | E25: 平面図 【目視】
B26: ⑥ 共同生活住居は、１以上のユニットを有するほか、日常生活を営む上で必要な設備を設けているか。 | C26: ⑥住居の中（ユニット）の設備とルール 【現場でのチェック】ご利用者が過ごしやすく、交流できる環境になっていますか？ | D26: 平18厚令171 第210条第6項 | E26: 平面図 設備・備品等一覧表 【目視】
B27: ⑦ ユニットの入居定員は、2人以上10人以下となっているか。 | C27: ⑦ユニットの定員： 1つの生活単位（ユニット）の定員は2人以上 10人以下に収まっているか。 | D27: 平18厚令171 第210条第7項 | E27: 平面図 【目視】
B28: ⑧ ユニットには、居室及び居室に近接して設けられる相互に交流を図ることができる設備を設けているか。その基準は次のとおりとなっているか。 ア １の居室の定員は、１人とすること。 （ただし、利用者のサービス提供上必要と認められる場合は、２人とすることができる。） イ １の居室の面積は、収納設備等を除き、7．43平方メートル以上とすること。 | C28: ⑧交流スペースの設置： ご利用者の居室の近くに、みんなで集まって交流できるリビングや食堂などのスペースがあるか。 お部屋（居室）のルール： ・原則1人部屋： ご利用者へのサービス提供上で特に必要な場合を除き、1人1部屋（個室）になっているか。 ・広さの確保： お部屋の広さは、備え付けの収納（クローゼットなど）を除いたスペースで7.43平方メートル（約4.5畳）以上あるか。 | D28: 平18厚令171 第210条第8項 | E28: 平面図 設備・備品等一覧表 【目視】
B29: ⑨ サテライト型住居の基準は、次のとおりとなっているか。 ア 入居定員を１人とすること。 イ 日常生活を営む上で必要な設備を設けること。 ウ 居室の面積は、収納設備等を除き、7．43平方メートル以上とすること。 | C29: ⑨サテライト型住居のルール 【現場でのチェック】一人暮らしに近い「サテライト型」の基準を満たしていますか？ ・定員は1人： サテライト型住居の定員は必ず1人であること。 ・必要な設備の設置： 独立して日常生活を送るために必要な設備（キッチン、お風呂、トイレなど）がきちんと備わっているか。 ・広さの確保： 一般の居室と同じく、収納スペースを除いて7.43平方メートル以上の広さがあるか。 | D29: 平18厚令171 第210条第9項 | E29: 平面図 設備・備品等一覧表 【目視】
B30: （経過措置） （１）平成18年厚生労働省令第171号（指定障害福祉サービス基準）の施行日（施行日）において現に入所施設又は病院の敷地内に存する建物を共同生活住居として指定共同生活援助の事業を行う指定共同生活援助事業者は、第3の①の規定にかかわらず、当該建物を共同生活住居とする指定共同生活援助の事業を行うことができる。 | C30: ※（経過措置）：平成18年（2006年）の制度スタート時からすでに入所施設や病院の敷地内にあった建物については、特例としてそのまま認められます。 | D30: 平18厚令171 附則第12条 | E30: 適宜必要と認める資料 | F30: 指定通知書、開設時の指定申請書控え、建物登記事項証明書、建築確認済証、賃貸借契約書、当時の平面図、敷地配置図、写真、行政との協議記録
B31: （２）指定共同生活援助事業者は、施行日において現に存する指定共同生活援助事業所において、指定共同生活援助の事業を行う場合には、当該事業所の共同生活住居（基本的な設備が完成しているものを含み、指定障害福祉サービス基準の施行の後に増築され、又は改築される等建物の構造を変更したものを除く。）が満たすべき設備に関する基準については、第3の⑦及び⑧の規定にかかわらず、平成18年厚生労働省令第58号（旧指定基準）第109条第2項及び第3項に定める基準によることができる。 | D31: 平18厚令171 附則第18条 | E31: 適宜必要と認める資料 | F31: 指定申請書控え、検査済証、増改築履歴、修繕履歴、建物登記事項証明書、賃貸借契約書、設備状況が分かる写真、行政確認記録
B32: （３）施行日において現に存する身体障害者福祉ホーム、精神障害者生活訓練施設、指定知的障害者通勤寮若しくは知的障害者福祉ホーム又は旧精神障害者福祉ホ－ム（基本的な設備が完成しているものを含み、指定障害福祉サービス基準の施行の後に増築され、又は改築される等建物の構造を変更したものを除く。）において行われる指定共同生活援助の事業について、第3の規定を適用する場合においては、当分の間、第3の⑦中「2人以上10人以下」とあるのは「2人以上30人以下」とし、第3の⑧のイの規定は、旧精神障害者福祉ホーム(障害者総合支援法施行令附則第8条の2に規定する厚生労働大臣が定めるものを除く。)を除き、当分の間、適用しない。 | D32: 平18厚令171 附則第19条 | E32: 適宜必要と認める資料 | F32: 旧施設時代の指定通知書・認可書、移行時の指定申請書、定員変更届、平面図、建物登記事項証明書、建築確認済証、増改築履歴、行政協議記録
A33: 確認項目 | B33: 確認事項 | C33: チェックポイント | D33: 根拠法令 | E33: 関係書類
A34: 第４ 運営に関する基準 | D34: 法第43条第2項
A35: １ 内容及び手続の説明及び同意 | B35: （１）指定共同生活援助事業者は、支給決定障害者等が指定共同生活援助の利用の申込みを行ったときは、当該利用申込者に係る障害の特性に応じた適切な配慮をしつつ、当該利用申込者に対し、運営規程の概要、従業者の勤務体制、その他の利用申込者のサービスの選択に資すると認められる重要事項を記した文書を交付して説明を行い、当該指定共同生活援助の提供の開始について当該利用申込者の同意を得ているか。 | C35: ・契約前に、ご利用者やご家族に重要事項説明書などを使い、サービス内容や料金を分かりやすく説明して、文書で同意（サイン）をもらっていますか？ | D35: 平18厚令171 第213条 準用（第9条第1項） | E35: 重要事項説明書 利用契約書
B36: （２）指定共同生活援助事業者は、社会福祉法第77条の規定に基づき書面の交付を行う場合は、利用者の障害の特性に応じた適切な配慮をしているか。 | D36: 平18厚令171 第213条 準用（第9条 第2項） | E36: 重要事項説明書 利用契約書 その他利用者に交付した書面
A37: ２ 提供拒否の禁止 | B37: 指定共同生活援助事業者は、正当な理由がなく、指定共同生活援助の提供を拒んでいないか。 | C37: ・「相性が悪そう」「対応が大変そう」といった事業所側の理由で、ご利用者の受け入れを断っていませんか？（拒否するには正当な理由が必要です） | D37: 平18厚令171 第213条 準用（第11条） | E37: 適宜必要と認める資料 | F37: 問い合わせ/見学記録(受入困難と判断した理由が書かれているか)
A38: ３ 連絡調整に対する協力 | B38: 指定共同生活援助事業者は、指定共同生活援助の利用について市町村又は一般相談支援事業若しくは特定相談支援事業を行う者が行う連絡調整に、できる限り協力しているか。 | C38: ・他の施設や相談支援専門員から、ご利用者の退去や転居に伴う調整、状況確認の連絡が来たとき、スムーズに協力していますか？ | D38: 平18厚令171 第213条 準用（第12条） | E38: 適宜必要と認める資料 | F38: 相談支援専門員、市町村との連絡記録(または日誌)
A39: ４ 受給資格の確認 | B39: 指定共同生活援助事業者は、指定共同生活援助の提供を求められた場合は、その者の提示する受給者証によって、支給決定の有無、支給決定の有効期間、支給量等を確かめているか。 | C39: ・ご利用者の受給者証をしっかり確認し、サービスの支給決定期間が切れていないか、負担上限月額がいくらになっているかを正確に把握していますか？ | D39: 平18厚令171 第213条 準用（第14条） | E39: 受給者証の写し
A40: ５ 訓練等給付費の支給の申請に係る援助 | B40: （１）指定共同生活援助事業者は、共同生活援助に係る支給決定を受けていない者から利用の申込みがあった場合は、その者の意向を踏まえて速やかに訓練等給付費の支給の申請が行われるよう必要な援助を行っているか。 | C40: ・ご利用者が受給者証の更新や申請手続きをするとき、本人が困らないよう必要に応じて手続きのお手伝いをしていますか？ | D40: 平18厚令171 第213条 準用（第15条 第1項） | E40: 適宜必要と認める資料 | F40: 仮申込書（相談対応・サポートした記録が残っているか）
...

Sheet 指定共同生活援助（日中サービス支援型）
A1: （注）下線を付した項目が標準確認項目
A2: 確認項目 | B2: 確認事項 | C2: 根拠法令 | D2: 関係書類 | E2: 確認書類（１つ） | F2: 判定
A3: 第７ 日中サービス支援型指定共同生活援助の事業の設備に関する基準 | C3: 法第43条第2項
B4: ① 日中サービス支援型指定共同生活援助に係る共同生活住居は、住宅地又は住宅地と同程度に利用者の家族や地域住民との交流の機会が確保される地域にあり、かつ、入所施設又は病院の敷地外にあるようになっているか。 | C4: 平18厚令171 第213条の6 第1項 | D4: 建物の周辺図 平面図 【目視】
B5: ② 日中サービス支援型指定共同生活援助事業所は、1以上の共同生活住居を有するものとし、当該共同生活住居の入居定員の合計は4人以上となっているか。 | C5: 平18厚令171 第213条の6 第2項 | D5: 平面図 【目視】
B6: ③ 共同生活住居の配置、構造及び設備は、利用者の特性に応じて工夫したものとなっているか。 | C6: 平18厚令171 第213条の6 第3項 | D6: 平面図 設備・備品等一覧表 【目視】
B7: ④ 共同生活住居は、その入居定員は2人以上10人以下となっているか。 ただし、構造上、共同生活住居ごとの独立性が確保されており、利用者の支援に支障がない場合で、1つの建物に複数の共同生活住居を設けた場合において、1つの建物の入居定員の合計は20人以下となっているか。 | C7: 平18厚令171 第213条の6 第4項 | D7: 平面図 【目視】
B8: ⑤ 既存の建物を共同生活住居とする場合にあっては、当該共同生活住居の入居定員を2人以上20人(都道府県知事（指定都市及び中核市にあっては、指定都市又は中核市の市長。）が特に必要があると認めるときは30人)以下となっているか。 | C8: 平18厚令171 第213条の6 第5項 | D8: 平面図 【目視】
B9: ⑥ 既存の建物を共同生活住居とした共同生活住居を改築する場合であって、都道府県知事が特に必要があると認めるときは、④及び⑤の規定にかかわらず、当該共同生活住居の入居定員は2人以上30人以下（ただし、当該共同生活住居を改築する時点の入居定員と同数を上限とする。）となっているか。 | C9: 平18厚令171 第213条の6 第6項 | D9: 平面図 【目視】
B10: ⑦ 共同生活住居は、１以上のユニットを有するほか、日常生活を営む上で必要な設備を設けているか。 | C10: 平18厚令171 第213条の6 第7項 | D10: 平面図 設備・備品等一覧表 【目視】
B11: ⑧ ユニットの入居定員は、2人以上10人以下となっているか。 | C11: 平18厚令171 第213条の6 第8項 | D11: 平面図 【目視】
B12: ⑨ ユニットには、居室及び居室に近接して設けられる相互に交流を図ることができる設備を設けているか。その基準は次のとおりとなっているか。 ア 1の居室の定員は、1人とすること。 （ただし、利用者のサービス提供上必要と認められる場合は、2人とすることができる。） イ 1の居室の面積は、収納設備等を除き、7．43平方メートル以上とすること。 | C12: 平18厚令171 第213条の6 第9項 | D12: 平面図 設備・備品等一覧表 【目視】
A13: 第８ 日中サービス支援型指定共同生活援助の事業の運営に関する基準 | C13: 法第43条第2項
A14: １ 内容及び手続の説明及び同意 | B14: （１）日中サービス支援型指定共同生活援助事業者は、支給決定障害者等が日中サービス支援型指定共同生活援助の利用の申込みを行ったときは、当該利用申込者に係る障害の特性に応じた適切な配慮をしつつ、当該利用申込者に対し、運営規程の概要、従業者の勤務体制、その他の利用申込者のサービスの選択に資すると認められる重要事項を記した文書を交付して説明を行い、当該日中サービス支援型指定共同生活援助の提供の開始について当該利用申込者の同意を得ているか。 | C14: 平18厚令171 第213条の11 準用（第9条第1項） | D14: 重要事項説明書 利用契約書
B15: （２）日中サービス支援型指定共同生活援助事業者は、社会福祉法第77条の規定に基づき書面の交付を行う場合は、利用者の障害の特性に応じた適切な配慮をしているか。 | C15: 平18厚令171 第213条の11 準用（第9条 第2項） | D15: 重要事項説明書 利用契約書 その他利用者に交付した書面
A16: ２ 提供拒否の禁止 | B16: 日中サービス支援型指定共同生活援助事業者は、正当な理由がなく、日中サービス支援型指定共同生活援助の提供を拒んでいないか。 | C16: 平18厚令171 第213条の11 準用（第11条） | D16: 適宜必要と認める資料 | E16: 利用申込受付簿
A17: ３ 連絡調整に対する協力 | B17: 日中サービス支援型指定共同生活援助事業者は、日中サービス支援型指定共同生活援助の利用について市町村又は一般相談支援事業若しくは特定相談支援事業を行う者が行う連絡調整に、できる限り協力しているか。 | C17: 平18厚令171 第213条の11 準用（第12条） | D17: 適宜必要と認める資料 | E17: 相談支援専門員との連絡記録
A18: ４ 受給資格の確認 | B18: 日中サービス支援型指定共同生活援助事業者は、日中サービス支援型指定共同生活援助の提供を求められた場合は、その者の提示する受給者証によって、支給決定の有無、支給決定の有効期間、支給量等を確かめているか。 | C18: 平18厚令171 第213条の11 準用（第14条） | D18: 受給者証の写し
A19: ５ 訓練等給付費の支給の申請に係る援助 | B19: （１）日中サービス支援型指定共同生活援助事業者は、日中サービス支援型共同生活援助に係る支給決定を受けていない者から利用の申込みがあった場合は、その者の意向を踏まえて速やかに訓練等給付費の支給の申請が行われるよう必要な援助を行っているか。 | C19: 平18厚令171 第213条の11 準用（第15条 第1項） | D19: 適宜必要と認める資料 | E19: 利用申込記録
B20: （２）日中サービス支援型指定共同生活援助事業者は、日中サービス支援型共同生活援助に係る支給決定に通常要すべき標準的な期間を考慮し、支給決定の有効期間の終了に伴う訓練等給付費の支給申請について、必要な援助を行っているか。 | C20: 平18厚令171 第213条の11 準用（第15条 第2項） | D20: 適宜必要と認める資料 | E20: 受給者証期限管理表
A21: ６ 心身の状況等の把握 | B21: 日中サービス支援型指定共同生活援助事業者は、日中サービス支援型指定共同生活援助の提供に当たっては、利用者の心身の状況、その置かれている環境、他の保健医療サービス又は福祉サービスの利用状況等の把握に努めているか。 | C21: 平18厚令171 第213条の11 準用（第16条） | D21: アセスメント記録 ケース記録
A22: ７ 指定障害福祉サービス事業者等との連携等 | B22: （１）日中サービス支援型指定共同生活援助事業者は、日中サービス支援型指定共同生活援助を提供するに当たっては、地域及び家庭との結び付きを重視した運営を行い、市町村、他の指定障害福祉サービス事業者等その他の保健医療サービス又は福祉サービスを提供する者との密接な連携に努めているか。 | C22: 平18厚令171 第213条の11 準用（第17条第1項） | D22: 個別支援計画 ケース記録
B23: （２）日中サービス支援型指定共同生活援助事業者は、日中サービス支援型指定共同生活援助の提供の終了に際しては、利用者又はその家族に対して適切な援助を行うとともに、保健医療サービス又は福祉サービスを提供する者との密接な連携に努めているか。 | C23: 平18厚令171 第213条の11 準用（第17条第2項） | D23: 個別支援計画 ケース記録
A24: ８ サービスの提供の記録 | B24: （１）日中サービス支援型指定共同生活援助事業者は、日中サービス支援型指定共同生活援助を提供した際は、当該日中サービス支援型指定共同生活援助の提供日、内容その他必要な事項を記録しているか。 | C24: 平18厚令171 第213条の11 準用（第53条の2第1項） | D24: サービス提供の記録
B25: （２）日中サービス支援型指定共同生活援助事業者は、(1)の規定による記録に際しては、支給決定障害者等から日中サービス支援型指定共同生活援助を提供したことについて確認を受けているか。 | C25: 平18厚令171 第213条の11 準用（第53条の2第2項） | D25: サービス提供の記録
A26: ９ 入退居 | B26: （１）日中サービス支援型指定共同生活援助は、共同生活住居への入居を必要とする利用者(入院治療を要する者を除く。)に提供されているか。 | C26: 平18厚令171 第213条の11 準用（第210条の2第1項） | D26: 個別支援計画 サービス提供の記録 アセスメント記録
B27: （２）日中サービス支援型指定共同生活援助事業者は、利用申込者の入居に際しては、その者の心身の状況、生活歴、病歴等の把握に努めているか。 | C27: 平18厚令171 第213条の11 準用（第210条の2第2項） | D27: 個別支援計画 アセスメント記録 サービス担当者会議の記録
B28: （３）日中サービス支援型指定共同生活援助事業者は、利用者の退居の際は、利用者の希望を踏まえた上で、退居後の生活環境や援助の継続性に配慮し、退居に必要な援助を行い、又はこれに併せて居宅における自立した日常生活への移行後の定着に必要な援助を行っているか。 | C28: 平18厚令171 第213条の11 準用（第210条の2第3項） | D28: ケース記録 サービス提供の記録
B29: （４）日中サービス支援型指定共同生活援助事業者は、利用者の退居に際しては、利用者に対し、適切な援助を行うとともに、保健医療サービス又は福祉サービスを提供する者との密接な連携に努めているか。 | C29: 平18厚令171 第213条の11 準用（第210条の2第4項） | D29: 他サービスとの連携状況が分かる書類（ケース記録、サービス提供の記録等）
A30: 10 入退居の記録の記載等 | B30: （１）日中サービス支援型指定共同生活援助事業者は、入居者の入居又は退居に際しては、当該日中サービス支援型指定共同生活援助事業者の名称、入居又は退居の年月日その他の必要な事項(受給者証記載事項）を利用者の受給者証に記載しているか。 | C30: 平18厚令171 第213条の11 準用（第210条の3第1項） | D30: 適宜必要と認める資料 | E30: 受給者証写し
B31: （２）日中サービス支援型指定共同生活援助事業者は、受給者証記載事項その他必要な事項を遅滞なく市町村に対し報告しているか。 | C31: 平18厚令171 第213条の11 準用（第210条の3第2項） | D31: 適宜必要と認める資料 | E31: 契約内容報告書の提出控え
A32: 11 日中サービス支援型指定共同生活援助事業者が支給決定障害者等に求めることのできる金銭の支払の範囲等 | B32: （１）日中サービス支援型指定共同生活援助事業者が、日中サービス支援型指定共同生活援助を提供する支給決定障害者等に対して金銭の支払を求めることができるのは、当該金銭の使途が直接利用者の便益を向上させるものであって、当該支給決定障害者等に支払を求めることが適当であるものに限られているか。 | C32: 平18厚令171 第213条の11 準用（第20条 第1項) | D32: 適宜必要と認める資料 | E32: 重要事項説明書
B33: （２）(1)の規定により金銭の支払を求める際は、当該金銭の使途及び額並びに支給決定障害者等に金銭の支払を求める理由について書面によって明らかにするとともに、支給決定障害者等に対し説明を行い、その同意を得ているか。 | C33: 平18厚令171 第213条の11 準用（第20条 第2項） | D33: 適宜必要と認める資料 | E33: 重要事項説明書
B34: （ただし、12の(1)から(3)までに掲げる支払については、この限りでない。）
A35: 12 利用者負担額等の受領 | B35: （１）日中サービス支援型指定共同生活援助事業者は、日中サービス支援型指定共同生活援助を提供した際は、支給決定障害者から当該日中サービス支援型指定共同生活援助に係る利用者負担額の支払を受けているか。 | C35: 平18厚令171 第213条の11 準用（第210条の4第1項） | D35: 請求書 領収書
B36: （２）日中サービス支援型指定共同生活援助事業者は、法定代理受領を行わない日中サービス支援型指定共同生活援助を提供した際は、支給決定障害者から当該日中サービス支援型指定共同生活援助に係る指定障害福祉サービス等費用基準額の支払を受けているか。 | C36: 平18厚令171 第213条の11 準用（第210条の4第2項） | D36: 請求書 領収書
B37: （３）日中サービス支援型指定共同生活援助事業者は、(1)及び(2)の支払を受ける額のほか、日中サービス支援型指定共同生活援助において提供される便宜に要する費用のうち、支給決定障害者から受けることのできる次に掲げる費用の支払を受けているか。 | C37: 平18厚令171 第213条の11 準用（第210条の4第3項） | D37: 請求書 領収書
B38: ① 食材料費
B39: ② 家賃(障害者総合支援法第34条第1項の規定により特定障害者特別給付費が利用者に支給された場合(同条第2項において準用する同法第29条第4項の規定により特定障害者特別給付費が利用者に代わり当該日中サービス支援型指定共同生活援助事業者に支払われた場合に限る。)は、当該利用者に係る家賃の月額から同法第34条第2項において準用する同法第29条第5項の規定により当該利用者に支給があったものとみなされた特定障害者特別給付費の額を控除した額を限度とする。)
B40: ③ 光熱水費
...

Sheet 指定共同生活援助（外部サービス利用型）
A2: （注）下線を付した項目が標準確認項目
A3: 確認項目 | B3: 確認事項 | C3: 根拠法令 | D3: 関係書類 | E3: 確認書類（１つ） | F3: 判定
A4: 第９ 外部サービス利用型指定共同生活援助の事業の基本方針 | C4: 法第43条
B5: （１）外部サービス利用型指定共同生活援助事業者は、利用者の意向、適性、障害の特性その他の事情を踏まえた計画（個別支援計画）を作成し、これに基づき利用者に対して外部サービス利用型指定共同生活援助を提供するとともに、その効果について継続的な評価を実施することその他の措置を講ずることにより利用者に対して適切かつ効果的に外部サービス利用型指定共同生活援助を提供しているか。 | C5: 平18厚令171 第3条第1項 | D5: 運営規程 個別支援計画 ケース記録
B6: （２）外部サービス利用型指定共同生活援助事業者は、利用者の意思及び人格を尊重して、常に当該利用者の立場に立った外部サービス利用型指定共同生活援助の提供に努めているか。 | C6: 平18厚令171 第3条第2項 | D6: 運営規程 個別支援計画 ケース記録
B7: （３）外部サービス利用型指定共同生活援助事業者は、利用者の人権の擁護、虐待の防止等のため、必要な体制の整備を行うとともに、その従業者に対し、研修を実施する等の措置を講じているか。 | C7: 平18厚令171 第3条第3項 | D7: 運営規程 研修計画、研修実施記録 虐待防止関係書類 体制の整備をしていることが分かる書類
B8: （４）外部サービス利用型指定共同生活援助の事業は、外部サービス利用型共同生活援助計画に基づき、受託居宅介護サービス事業者による受託居宅介護サービスを適切かつ円滑に提供することにより、利用者が地域において共同して自立した日常生活又は社会生活を営むことができるよう、当該利用者の身体及び精神の状況並びにその置かれている環境に応じて共同生活住居において、相談、入浴、排泄若しくは食事の介護その他の日常生活上の援助又はこれに併せて行われる居宅における自立した日常生活への移行及び移行後の定着に必要な援助を適切かつ効果的に行っているか。 | C8: 平18厚令171 第213条の13 | D8: 運営規程 個別支援計画 ケース記録
A9: 第10 外部サービス利用型指定共同生活援助の事業の人員に関する基準 | C9: 法第43条第1項
A10: １ 外部サービス利用型指定共同生活援助事業所の従業者の員数 | B10: 外部サービス利用型指定共同生活援助事業所に置くべき基本サービスを提供する従業者及びその員数は、次のとおりになっているか。 | C10: 平18厚令171 第213条の14 第1項
A11: （１）世話人 | B11: 外部サービス利用型指定共同生活援助事業所ごとに、常勤換算方法で、利用者の数を6で除した数以上となっているか。（ただし、平成26年4月1日に現に存する指定共同生活援助事業所における世話人の員数については、当分の間、常勤換算方法で、当該外部サービス利用型指定共同生活援助事業所の利用者の数を10で除した数以上となっているか。） | C11: 平18厚令171 第213条の14 第1項第1号 | D11: 勤務実績表 出勤簿（タイムカード） 従業員の資格証 勤務体制一覧表 利用者数（平均利用人数）が分かる書類（実績表等）
A12: （２）サービス管理責任者 | B12: 外部サービス利用型指定共同生活援助事業所ごとに、①又は②に掲げる利用者の数の区分に応じ、それぞれ①又は②に掲げる数となっているか。 ① 利用者の数が30以下 1以上 ② 利用者の数が31以上 1に利用者の数が30を超えて30又はその端数を増すごとに1を加えて得た数以上 | C12: 平18厚令171 第213条の14 第1項第2号 | D12: 勤務実績表 出勤簿（タイムカード） 従業員の資格証 勤務体制一覧表 利用者数（平均利用人数）が分かる書類（実績表等）
A13: （３）利用者数の 算定 | B13: (1)及び(2)の利用者の数は、前年度の平均値となっているか。ただし、新規に指定を受ける場合は、適切な推定数により算定されているか。 | C13: 平18厚令171 第213条の14 第2項 | D13: 利用者数（平均利用人数）が分かる書類（利用者名簿等）
A14: （４）職務の専従 | B14: (1)及び(2)に規定する外部サービス利用型指定共同生活援助事業者の従業者は､専ら外部サービス利用型指定共同生活援助事業所の職務に従事する者となっているか。 （ただし、利用者の支援に支障がない場合はこの限りでない。） | C14: 平18厚令171 第213条の14 第3項 | D14: 従業者の勤務実態の分かる書類 （出勤簿等）
A15: （５）管理者 | B15: ① 外部サービス利用型指定共同生活援助事業所ごとに専らその職務に従事する常勤の管理者を置いているか。 （ただし、外部サービス利用型指定共同生活援助事業所の管理上支障がない場合は、当該外部サービス利用型指定共同生活援助事業所の他の職務に従事させ、又は他の事業所、施設等の職務に従事させることができる。） | C15: 平18厚令171 第213条の14 第3項 | D15: 管理者の雇用形態が分かる書類 管理者の勤務実績表（タイムカード）
B16: ② 外部サービス利用型指定共同生活援助事業所の管理者は、適切な外部サービス利用型指定共同生活援助を提供するために必要な知識及び経験を有する者となっているか。 | C16: 平18厚令171 第213条の15 準用（第209条第2項） | D16: 管理者に必要な知識や経験があることが分かる書類（資格証、研修修了証等）
A17: 第11 外部サービス利用型指定共同生活援助の事業の設備に関する基準 | C17: 法第43条第2項
B18: ① 外部サービス利用型指定共同生活援助に係る共同生活住居は、住宅地又は住宅地と同程度に利用者の家族や地域住民との交流の機会が確保される地域にあり、かつ、入所により日中及び夜間を通してサービスを提供する施設（入所施設）又は病院の敷地外にあるようになっているか。 | C18: 平18厚令171 第213条の16 準用（第210条第1項） | D18: 建物の周辺図 平面図 【目視】
B19: ② 外部サービス利用型指定共同生活援助事業所は、１以上の共同生活住居（サテライト型住居を除く。以下この②、④から⑥までにおいて同じ。）を有するものとし、当該共同生活住居及びサテライト型住居の入居定員の合計は4人以上となっているか。 | C19: 平18厚令171 第213条の16 準用（第210条第2項） | D19: 平面図 【目視】
B20: ③ 共同生活住居の配置、構造及び設備は、利用者の特性に応じて工夫したものとなっているか。 | C20: 平18厚令171 第213条の16 準用（第210条第3項） | D20: 平面図 設備・備品等一覧表 【目視】
B21: ④ 共同生活住居は、その入居定員は2人以上10人以下となっているか。 ただし、既存の建物を共同生活住居とする場合にあっては、当該共同生活住居の入居定員は2人以上20人（都道府県知事（指定都市及び中核市にあっては、指定都市又は中核市の市長。）が特に必要があると認めるときは30人）以下となっているか。 | C21: 平18厚令171 第213条の16 準用（第210条第4項） | D21: 平面図 【目視】
B22: ⑤ 既存の建物を共同生活住居とした共同生活住居を改築する場合であって、都道府県知事が特に必要があると認めるときは、④の規定にかかわらず、当該共同生活住居の入居定員は2人以上30人以下（ただし、当該共同生活住居を改築する時点の入居定員と同数を上限とする。）となっているか。 | C22: 平18厚令171 第213条の16 準用（第210条第5項） | D22: 平面図 【目視】
B23: ⑥ 共同生活住居は、１以上のユニットを有するほか、日常生活を営む上で必要な設備を設けているか。 | C23: 平18厚令171 第213条の16 準用（第210条第6項） | D23: 平面図 設備・備品等一覧表 【目視】
B24: ⑦ ユニットの入居定員は、2人以上10人以下となっているか。 | C24: 平18厚令171 第213条の16 準用（第210条第7項） | D24: 平面図 【目視】
B25: ⑧ ユニットには、居室及び居室に近接して設けられる相互に交流を図ることができる設備を設けているか。その基準は次のとおりとなっているか。 ア １の居室の定員は、１人とすること。 （ただし、利用者のサービス提供上必要と認められる場合は、２人とすることができる。） イ １の居室の面積は、収納設備等を除き、7．43平方メートル以上とすること。 | C25: 平18厚令171 第213条の16 準用（第210条第8項） | D25: 平面図 設備・備品等一覧表 【目視】
B26: ⑨ サテライト型住居の基準は、次のとおりとなっているか。 ア 入居定員を１人とすること。 イ 日常生活を営む上で必要な設備を設けること。 ウ 居室の面積は、収納設備等を除き、7．43平方メートル以上とすること。 | C26: 平18厚令171 第213条の16 準用（第210条第9項） | D26: 平面図 設備・備品等一覧表 【目視】
B27: （経過措置）
B28: （１）平成18年厚生労働省令第171号（指定障害福祉サービス基準）の施行日（施行日）において現に入所施設又は病院の敷地内に存する建物を共同生活住居として指定共同生活援助の事業を行う外部サービス利用型指定共同生活援助事業者は、第11の①の規定にかかわらず、当該建物を共同生活住居とする外部サービス利用型指定共同生活援助の事業を行うことができる。 | C28: 平18厚令171 附則第12条 | D28: 適宜必要と認める資料 | E28: 施行日時点の指定通知書
B29: （２）外部サービス利用型指定共同生活援助事業者は、施行日において現に存する共同生活援助事業所において、外部サービス利用型指定共同生活援助の事業を行う場合には、当該事業所の共同生活住居（基本的な設備が完成しているものを含み、指定障害福祉サービス基準の施行の後に増築され、又は改築される等建物の構造を変更したものを除く。）が満たすべき設備に関する基準については、第11の⑦及び⑧の規定にかかわらず、平成18年厚生労働省令第58号（旧指定基準）第109条第2項及び第3項に定める基準によることができる。 | C29: 平18厚令171 附則第18条 | D29: 適宜必要と認める資料 | E29: 旧指定基準時代の指定通知書
B30: （３）施行日において現に存する身体障害者福祉ホーム、精神障害者生活訓練施設、指定知的障害者通勤寮若しくは知的障害者福祉ホーム又は旧精神障害者福祉ホ－ム（基本的な設備が完成しているものを含み、指定障害福祉サービス基準の施行の後に増築され、又は改築される等建物の構造を変更したものを除く。）において行われる外部サービス利用型指定共同生活援助の事業について、第7の規定を適用する場合においては、当分の間、第11の⑦中「2人以上10人以下」とあるのは「2人以上30人以下」とし、第11の⑧のイの規定は、旧精神障害者福祉ホーム(障害者総合支援法施行令附則第8条の2に規定する厚生労働大臣が定めるものを除く。)を除き、当分の間、適用しない。 | C30: 平18厚令171 附則第19条 | D30: 適宜必要と認める資料 | E30: 旧施設種別の指定通知書
A31: 第12 外部サービス利用型指定共同生活援助の事業の運営に関する基準 | C31: 法第43条第2項
A32: １ 内容及び手続の説明及び同意 | B32: （１）外部サービス利用型指定共同生活援助事業者は、支給決定障害者等が外部サービス利用型指定共同生活援助の利用の申込みを行ったときは、当該利用申込者に係る障害の特性に応じた適切な配慮をしつつ、当該利用申込者に対し、運営規程の概要、従業者の勤務体制、外部サービス利用型指定共同生活援助事業者と受託居宅介護サービス事業者の業務の分担の内容、受託居宅介護サービス事業者及び受託居宅介護サービス事業所の名称その他の利用申込者のサービスの選択に資すると認められる重要事項を記した文書を交付して説明を行い、当該外部サービス利用型指定共同生活援助の提供の開始について当該利用申込者の同意を得ているか。 | C32: 平18厚令171 第213条の17 第1項 | D32: 重要事項説明書 利用契約書
B33: （２）外部サービス利用型指定共同生活援助事業者は、社会福祉法第77条の規定に基づき、書面の交付を行う場合は、利用者の障害の特性に応じた適切な配慮をしているか。 | C33: 平18厚令171 第213条の17 第2項 | D33: 重要事項説明書 利用契約書 その他利用者に交付した書面
A34: ２ 提供拒否の禁止 | B34: 外部サービス利用型指定共同生活援助事業者は、正当な理由がなく、外部サービス利用型指定共同生活援助の提供を拒んでいないか。 | C34: 平18厚令171 第213条の22 準用（第11条） | D34: 適宜必要と認める資料 | E34: 利用申込受付票
A35: ３ 連絡調整に対する協力 | B35: 外部サービス利用型指定共同生活援助事業者は、外部サービス利用型指定共同生活援助の利用について市町村又は一般相談支援事業若しくは特定相談支援事業を行う者が行う連絡調整に、できる限り協力しているか。 | C35: 平18厚令171 第213条の22 準用（第12条） | D35: 適宜必要と認める資料 | E35: 相談支援専門員との連絡記録
A36: ４ 受給資格の確認 | B36: 外部サービス利用型指定共同生活援助事業者は、外部サービス利用型指定共同生活援助の提供を求められた場合は、その者の提示する受給者証によって、支給決定の有無、支給決定の有効期間、支給量等を確かめているか。 | C36: 平18厚令171 第213条の22 準用（第14条） | D36: 受給者証の写し
A37: ５ 訓練等給付費の支給の申請に係る援助 | B37: （１）外部サービス利用型指定共同生活援助事業者は、外部サービス利用型共同生活援助に係る支給決定を受けていない者から利用の申込みがあった場合は、その者の意向を踏まえて速やかに訓練等給付費の支給の申請が行われるよう必要な援助を行っているか。 | C37: 平18厚令171 第213条の22 準用（第15条 第1項） | D37: 適宜必要と認める資料 | E37: 利用申込記録
B38: （２）外部サービス利用型指定共同生活援助事業者は、外部サービス利用型共同生活援助に係る支給決定に通常要すべき標準的な期間を考慮し、支給決定の有効期間の終了に伴う訓練等給付費の支給申請について、必要な援助を行っているか。 | C38: 平18厚令171 第213条の22 準用（第15条 第2項） | D38: 適宜必要と認める資料 | E38: 受給者証期限管理表
A39: ６ 心身の状況等の把握 | B39: 外部サービス利用型指定共同生活援助事業者は、外部サービス利用型指定共同生活援助の提供に当たっては、利用者の心身の状況、その置かれている環境、他の保健医療サービス又は福祉サービスの利用状況等の把握に努めているか。 | C39: 平18厚令171 第213条の22 準用（第16条） | D39: アセスメント記録 ケース記録
A40: ７ 指定障害福祉 サービス事業者等との連携等 | B40: （１）外部サービス利用型指定共同生活援助事業者は、外部サービス利用型指定共同生活援助を提供するに当たっては、地域及び家庭との結び付きを重視した運営を行い、市町村、他の指定障害福祉サービス事業者等その他の保健医療サービス又は福祉サービスを提供する者との密接な連携に努めているか。 | C40: 平18厚令171 第213条の22 準用（第17条第1項） | D40: 個別支援計画 ケース記録
B41: （２）外部サービス利用型指定共同生活援助事業者は、外部サービス利用型指定共同生活援助の提供の終了に際しては、利用者又はその家族に対して適切な援助を行うとともに、保健医療サービス又は福祉サービスを提供する者との密接な連携に努めているか。 | C41: 平18厚令171 第213条の22 準用（第17条第2項） | D41: 個別支援計画 ケース記録
...

Sheet 指定共同生活援助（訓練等給付費の算定）
A1: （注）下線を付した項目が標準確認項目
A2: 確認項目 | B2: 確認事項 | C2: 根拠法令 | D2: 関係書類 | E2: 関係書類 | F2: 判定
A3: 第14 介護給付費又は訓練等給付費の算定及び取扱い | C3: 法第29条第3項
A4: １ 基本事項 | B4: （１）指定共同生活援助又は外部サービス利用型指定共同生活援助に要する費用の額は、平成18年厚生労働省告示第523号の別表「介護給付費等単位数表」の第15により算定する単位数に、平成18年厚生労働省告示第539号「こども家庭庁長官及び厚生労働大臣が定める一単位の単価並びに厚生労働大臣が定める一単位の単価」に定める一単位の単価を乗じて得た額を算定しているか。 | C4: 平18厚告523 の一 平18厚告539 | D4: 体制等状況一覧表、当該加算の届出書等 | E4: 介護給付費等算定に係る体制等状況一覧表
B5: （ただし、その額が現に当該指定共同生活援助又は外部サービス利用型指定共同生活援助に要した費用の額を超えるときは、当該現に指定共同生活援助又は外部サービス利用型指定共同生活援助に要した費用の額となっているか。） | C5: 法第29条 第3項
B6: （２）(1)の規定により、指定共同生活援助又は外部サービス利用型指定共同生活援助に要する費用の額を算定した場合において、その額に1円未満の端数があるときは、その端数金額は切り捨てて算定しているか。 | C6: 平18厚告523の二 | D6: 体制等状況一覧表、当該加算の届出書等
A7: ２ 共同生活援助 サービス費 | B7: （１）共同生活援助サービス費（Ⅰ）については、障害者（身体障害者にあっては、65歳未満の者又は65歳に達する日の前日までに障害福祉サービス若しくはこれに準ずるものを利用したことがある者に限り、地域移行支援型ホームにおける指定共同生活援助の利用者にあっては、当該地域移行支援型ホームにおいて指定共同生活援助の事業を行う者が当該事業を開始した日において、精神科病院に1年以上入院している精神障害者に限る。）(3)において同じ。）（(3)に規定する障害者を除く。）に対し、指定共同生活援助事業所において、指定共同生活援助を行った場合に、障害支援区分に応じ、１日につき所定単位数を算定しているか。 | C7: 平18厚告523 別表第15の1の注1 | D7: 体制等状況一覧表、当該加算の届出書等 | E7: 請求明細書
B8: （２）令和9年3月31日までの間、指定共同生活援助事業所において、個人単位で居宅介護等を利用する場合の利用者に対し、指定共同生活援助を行った場合にあっては、(1)にかかわらず、次に掲げる単位数を算定しているか。ただし、これらの規定に基づく居宅介護又は重度訪問介護の利用について、所要時間が８時間以上である場合にあっては、次に掲げる単位数の100分の95に相当する単位数を算定しているか。 ア 区分6 369単位 イ 区分5 306単位 ウ 区分4 270単位 | C8: 平18厚告523 別表第15の1の 注2 | D8: 体制等状況一覧表、当該加算の届出書等
B9: （３）共同生活援助サービス費（Ⅱ）については、一時的に体験的な指定共同生活援助の利用が必要と認められる者に対し、指定共同生活援助（1回当たり連続30日以内のものに限る。）を提供した場合に、障害支援区分に応じ、年50日以内に限り、1日につき所定単位数を算定しているか。 | C9: 平18厚告523 別表第15の1の 注3 | D9: 体制等状況一覧表、当該加算の届出書等
B10: （４）共同生活援助サービス費（(2)に規定する場合を含む。）の算定に当たって、次の①から⑤までのいずれかに該当する場合に、それぞれに掲げる割合を所定単位数に乗じて得た数を算定しているか。 （ただし、③及び⑤に該当する場合にあっては、③に掲げる割合を所定単位数に乗じて得た額を、④及び⑤に該当する場合にあっては、④に掲げる割合を所定単位数に乗じて得た額を算定しているか。） | C10: 平18厚告523 別表第15の1の注４ | D10: 体制等状況一覧表、当該加算の届出書等
B11: ① 従業者の員数が平成18年厚生労働省告示第550号「厚生労働大臣が定める利用者の数の基準、従業者の員数の基準及び営業時間の時間数並びに所定単位数に乗じる割合並びにこども家庭庁長官及び厚生労働大臣が定める利用者の数の基準及び従業員の員数の基準並びに所定単位数に乗じる割合」の十の表の上欄に掲げる員数の基準に該当する場合 同表の下欄に掲げる割合 | C11: 平18厚告523 別表第15の1の注４の(1) 平18厚告550の十 | D11: 体制等状況一覧表、当該加算の届出書等
B12: ② 指定共同生活援助の提供に当たって、共同生活援助計画が作成されていない場合 次に掲げる場合に応じ、それぞれ次に掲げる割合 ア 作成されていない期間が3月未満の場合 100分の70 イ 作成されていない期間が3月以上の場合 100分の50 | C12: 平18厚告523 別表第15の1の 注４の（2） | D12: 体制等状況一覧表、当該加算の届出書等
B13: ③ 共同生活住居の入居定員が8人以上である場合 100分の95 | C13: 平18厚告523 別表第15の1の 注４の（3） | D13: 体制等状況一覧表、当該加算の届出書等
B14: ④ 共同生活住居の入居定員が21人以上である場合 100分の93 | C14: 平18厚告523 別表第15の1の 注４の（4） | D14: 体制等状況一覧表、当該加算の届出書等
B15: ⑤ 一体的な運営が行われている共同生活住居の入居定員（サテライト型住居に係る入居定員を含む。）の合計数が21人以上である場合 100分の95 | C15: 平18厚告523 別表第15の1の 注４の（5） | D15: 体制等状況一覧表、当該加算の届出書等
B16: （５）第76の３第１項の規定に基づく情報公表対象サービス等情報に係る報告を行っていない場合は、所定単位数の100分の10に相当する単位数を所定単位数から減算しているか。 | C16: 平18厚告523 別表第15の1の 注5 | D16: 体制等状況一覧表、当該加算の届出書等
B17: （６）第４の27の⑴（指定障害福祉サービス基準第213条において準用する指定障害福祉サービス基準第33条の２第１項）に規定する基準を満たしていない場合は、所定単位数の100分の３に相当する単位数を所定単位数から減算しているか。 | C17: 平18厚告523 別表第15の1の 注6 | D17: 体制等状況一覧表、当該加算の届出書等
B18: （７）第4の33の(2)又は(3)（指定障害福祉サービス基準第213条において準用する指定障害福祉サービス基準第35条の２第２項又は第3項）に規定する基準を満たしていない場合は、所定単位数の100分の10に相当する単位数を所定単位数から減算しているか。 | C18: 平18厚告523 別表第15の1の 注7 | D18: 体制等状況一覧表、当該加算の届出書等
B19: （８）第4の39（指定障害福祉サービス基準第213条において準用する指定障害福祉サービス基準第40条の２）に規定する基準を満たしていない場合は、所定単位数の100分の１に相当する単位数を所定単位数から減算しているか。 | C19: 平18厚告523 別表第15の1の 注8 | D19: 体制等状況一覧表、当該加算の届出書等
B20: （９）利用者が共同生活援助以外の障害福祉サービスを受けている間（居宅介護を受けている間（(2)の適用を受けている間に限る。）及び重度訪問介護を受けている間（(2)の適用を受けている間に限る。）を除く。）は、共同生活援助サービス費を算定していないか。 | C20: 平18厚告523 別表第15の1の 注9 | D20: 体制等状況一覧表、当該加算の届出書等
A21: ２の２ 日中サービス支援型共同生活援助サービス費 | B21: （１）日中サービス支援型共同生活援助サービス費（Ⅰ）については、障害者（身体障害者にあっては、65歳未満の者又は65歳に達する日の前日までに障害福祉サービス若しくはこれに準ずるものを利用したことがある者に限る。（5）において同じ。）（(5)に規定する障害者を除く。）に対して、日中サービス支援型指定共同生活援助事業所において、日中サービス支援型指定共同生活援助を行った場合に、所定単位数を算定しているか。 | C21: 平18厚告523 別表第15の1の2の注1 | D21: 体制等状況一覧表、当該加算の届出書等 | E21: 請求明細書
B22: （２）日中を共同生活住居（第5の(4)に規定する共同生活住居をいう。)以外の場所で過ごす利用者に対し、日中サービス支援型指定共同生活援助を行った場合は、所定単位数に代えて、次のアからカまでの場合に応じ、それぞれ1日につき次に掲げる単位数を算定しているか。ただし、(4)に規定する単位数を算定している場合は、算定しない。 ア 区分6 765単位 イ 区分5 627単位 ウ 区分4 539単位 エ 区分3 407単位 オ 区分2 270単位 カ 区分1以下 253単位 | C22: 平18厚告523 別表第15の1の2の注2 | D22: 体制等状況一覧表、当該加算の届出書等
B23: （３）令和9年3月31日までの間、日中サービス支援型指定共同生活援助事業所において、個人単位で居宅介護等を利用する場合の利用者に対し、日中サービス支援型指定共同生活援助を行った場合は、所定単位数に代えて、次のアからウまでの場合に応じ、それぞれ1日につき次に掲げる単位数を算定しているか。また、これらの規定に基づく居宅介護又は重度訪問介護の利用について、所要時間が８時間以上である場合にあっては、次に掲げる単位数の100分の95に相当する単位数を算定しているか。 ア 区分6 565単位 イ 区分5 505単位 ウ 区分4 467単位 | C23: 平18厚告523 別表第15の1の2の注3 | D23: 体制等状況一覧表、当該加算の届出書等
B24: （４）令和9年3月31日までの間、日中サービス支援型指定共同生活援助事業所において、個人単位で居宅介護等を利用する場合の利用者であって、日中を共同生活住居以外の場所で過ごす者に対し、日中サービス支援型指定共同生活援助を行った場合は、所定単位数に代えて、次のアからウまでの場合に応じ、それぞれ1日につき、次に掲げる単位数を算定しているか。また、これらの規定に基づく居宅介護又は重度訪問介護の利用について、所要時間が８時間以上である場合にあっては、次に掲げる単位数の100分の95に相当する単位数を算定しているか。 ア 区分6 454単位 イ 区分5 394単位 ウ 区分4 356単位 | C24: 平18厚告523 別表第15の1の2の注4 | D24: 体制等状況一覧表、当該加算の届出書等
B25: （５）日中サービス支援型共同生活援助サービス費（Ⅱ）については、一時的に体験的な日中サービス支援型指定共同生活援助の利用が必要と認められる障害者に対し、日中サービス支援型指定共同生活援助（1回当たり連続30日以内のものに限る。）を提供した場合に、障害支援区分に応じ、年50日以内に限り、1日につき所定単位数を算定しているか。 | C25: 平18厚告523 別表第15の1の2の注5 | D25: 体制等状況一覧表、当該加算の届出書等
B26: （６）日中サービス支援型指定共同生活援助事業所において、一時的に体験的な日中サービス支援型指定共同生活援助の利用が必要と認められる者であって、日中を当該共同生活住居以外の場所で過ごすものに対し、日中サービス支援型指定共同生活援助（1回当たり連続30日以内のものに限る。）を提供した場合は、所定単位数に代えて、次の①から⑥までの場合に応じ、年50日以内に限り、それぞれ１日につき次に掲げる所定単位数を算定 しているか。 ① 区分6 929単位 ② 区分5 787単位 ③ 区分4 695単位 ④ 区分3 546単位 ⑤ 区分2 408単位 ⑥ 区分1以下 389単位 | C26: 平18厚告523 別表第15の1の2の注6 | D26: 体制等状況一覧表、当該加算の届出書等
B27: （７）日中サービス支援型共同生活援助サービス費（(2)から(4)まで及び(6)に規定する場合を含む。）の算定に当たって、次の①から④までのいずれかに該当する場合に、それぞれ次に掲げる割合を所定単位数に乗じて得た数を算定しているか。 | C27: 平18厚告523 別表第15の1の2の注7 | D27: 体制等状況一覧表、当該加算の届出書等
B28: ① 従業者の員数が平成18年厚生労働省告示第550号「厚生労働大臣が定める利用者の数の基準、従業者の員数の基準及び営業時間の時間数並びに所定単位数に乗じる割合並びにこども家庭庁長官及び厚生労働大臣が定める利用者の数の基準及び従業者の員数の基準並びに所定単位数に乗じる割合」の十の二の表の上欄に掲げる員数の基準に該当する場合 同表の下欄に掲げる割合 | C28: 平18厚告523 別表第15の1の2の注7の(1) 平18厚告550の十の二 | D28: 体制等状況一覧表、当該加算の届出書等
B29: ② 日中サービス支援型指定共同生活援助の提供に当たって、日中サービス支援型共同生活援助計画が作成されていない場合 次に掲げる場合に応じ、それぞれ次に掲げる割合 ア 作成されていない期間が3月未満の場合 100分の70 イ 作成されていない期間が3月以上の場合 100分の50 | C29: 平18厚告523 別表第15の1の2の注7の（2） | D29: 体制等状況一覧表、当該加算の届出書等
B30: ③ 共同生活住居の入居定員が21人以上である場合 100分の93 | C30: 平18厚告523 別表第15の1の2の注7の（3） | D30: 体制等状況一覧表、当該加算の届出書等
B31: ④ 一体的な運営が行われている共同生活住居（③に該当する共同生活住居を除く。）の入居定員の合計数が21人以上である場合 100分の95 | C31: 平18厚告523 別表第15の1の2の注7の（4） | D31: 体制等状況一覧表、当該加算の届出書等
B32: （８）法第76の３第１項の規定に基づく情報公表対象サービス等情報に係る報告を行っていない場合は、所定単位数の100分の10に相当する単位数を所定単位数から減算しているか。 | C32: 平18厚告523 別表第15の1の2の注８ | D32: 体制等状況一覧表、当該加算の届出書等
B33: （９）第８の28の⑴（指定障害福祉サービス基準第213条の11において準用する指定障害福祉サービス基準第33条の２第１項）に規定する基準を満たしていない場合は、所定単位数の100分の３に相当する単位数を所定単位数から減算しているか。 | C33: 平18厚告523 別表第15の1の2の注９ | D33: 体制等状況一覧表、当該加算の届出書等
... B36: （12）利用者が日中サービス支援型共同生活援助以外の障害福祉サービスを受けている間（居宅介護を受けている間（(3)及び(4)の適用を受けている間に限る。）及び重度訪問介護を受けている間（(3)及び(4)の適用を受けている間に限る。）を除く。）は、日中サービス支援型共同生活援助サービス費を算定していないか。 | C36: 平18厚告523 別表第15の1の2の注12 | D36: 体制等状況一覧表、当該加算の届出書等
A37: ２の２の２ 外部サービス利用型共同生活援助サービス費 | B37: （１）外部サービス利用型共同生活援助サービス費（Ⅰ）については、障害者（身体障害者にあっては、65歳未満の者又は65歳に達する日の前日までに障害福祉サービス若しくはこれに準ずるものを利用したことがある者に限り、地域移行支援型ホームにおける外部サービス利用型指定共同生活援助の利用者にあっては、当該地域移行支援型ホームにおいて外部サービス利用型指定共同生活援助の事業を行う者が外部サービス利用型指定共同生活援助の事業を開始した日において精神科病院に1年以上入院している精神障害者に限る。）(2)及び(3)において同じ。）（(3)に規定する障害者を除く。）に対し、世話人が、常勤換算方法で、利用者の数を６で除して得た数以上配置されているものとして都道府県知事に届け出た外部サービス利用型指定共同生活援助事業所において、基本サービスを行った場合に、1日につき所定単位数を算定しているか。 | C37: 平18厚告523 別表第15の1の2の2の注1 | D37: 体制等状況一覧表、当該加算の届出書等 | E37: 請求明細書
B38: （２）外部サービス利用型共同生活援助サービス費（Ⅱ）については、障害者（(3)に規定する障害者を除く。）に対し、(1)に規定するもの以外の外部サービス利用型指定共同生活援助事業所（平成25年厚生労働省令第124号「地域社会における共生の実現に向けて新たな障害保健福祉施策を講ずるための関係法律の整備に関する法律の一部の施行に伴う関係省令の整備等に関する省令」の附則第4条の規定の適用を受ける外部サービス利用型指定共同生活援助事業所に限る。）において、基本サービスを行った場合に、1日につき所定単位数を算定しているか。 | C38: 平18厚告523 別表第15の1の 2の2の注2 | D38: 体制等状況一覧表、当該加算の届出書等
B39: （３）外部サービス利用型共同生活援助サービス費（Ⅲ）については、一時的に体験的な外部サービス利用型指定共同生活援助の利用が必要と認められる障害者に対し、基本サービス（1回当たり連続30日以内のものに限る。）を提供した場合に、年50日以内に限り、1日につき所定単位数を算定しているか。 | C39: 平18厚告523 別表第15の1の 2の2の注3 | D39: 体制等状況一覧表、当該加算の届出書等
B40: （４）外部サービス利用型共同生活援助サービス費の算定に当たって、次の①から④までのいずれかに該当する場合に、それぞれに掲げる割合を所定単位数に乗じて得た数を算定しているか。 | C40: 平18厚告523 別表第15の1の 2の2の注4 | D40: 体制等状況一覧表、当該加算の届出書等
B41: ① 従業者の員数が平成18年厚生労働省告示第550号「厚生労働大臣が定める利用者の数の基準、従業者の員数の基準及び営業時間の時間数並びに所定単位数に乗じる割合並びにこども家庭庁長官及び厚生労働大臣が定める利用者の数の基準及び従業者の員数の基準並びに所定単位数に乗じる割合」の十一の表の上欄に掲げる員数の基準に該当する場合 同表の下欄に掲げる割合 | C41: 平18厚告523 別表第15の1の2の2の注4の(1) 平18厚告550の十一
B42: ② 基本サービスの提供に当たって、外部サービス利用型共同生活援助計画が作成されていない場合 次に掲げる場合に応じ、それぞれ次に掲げる割合 ア 作成されていない期間が3月未満の場合 100分の70 イ 作成されていない期間が3月以上の場合 100分の50 | C42: 平18厚告523 別表第15の1の 2の2の注4の（2）
...
