Workbook
Name 氏名一覧: OFFSET('利用者マスタ'!$A$4,0,0,MAX(1,COUNTA('利用者マスタ'!$A$4:$A$60)),1)
Name 部屋一覧: OFFSET('M_部屋'!$A$4,0,0,MAX(1,COUNTA('M_部屋'!$A$4:$A$20)),1)
Name 区分一覧: OFFSET('M_区分'!$A$4,0,0,MAX(1,COUNTA('M_区分'!$A$4:$A$20)),1)
Name 送迎一覧: OFFSET('M_送迎'!$A$4,0,0,MAX(1,COUNTA('M_送迎'!$A$4:$A$15)),1)
Name 状態一覧: 'M_状態'!$A$4:$A$8
Name 送付先一覧: OFFSET('M_FAX送付先'!$A$4,0,0,MAX(1,COUNTA('M_FAX送付先'!$A$4:$A$24)),1)

Sheet 00_使い方
A1: ショートステイ・体験利用 管理台帳
A2: 入力するのは 01_予約入力 と、M_ で始まるマスタだけです。02〜09 は全て自動計算です。
A4: 画面の役割
A5: 02_カレンダー | B5: ★毎日見るのはここ。ふつうの月カレンダーの形で、日ごとに「どの部屋に誰がいるか」と入室・退室の時刻を表示します（「時刻を表示」を空欄にすると時刻を消せます）。連泊は ▶入所日 → 継続 → 退所日◀ と続けて出るので、いつからいつまでかが目で追えます。色は区分ごと（SS・無料・契約）。仮予約はグレーの斜体です。★対象月の変更もこのシートで行います。
A6: 03_帯表 | B6: 1人1行・横軸が1〜31日のガントチャートです。誰がどの期間を押さえているかを1か月分まとめて俯瞰できます。▶入所 ■連泊 ◀退所 ◆日帰り。白抜き（▷□◁◇）は仮予約です。★その下に「当月の予約明細」があり、01_予約入力 の内容（部屋・区分・入退所の日時・泊数・状態・備考）が入所日順に自動で並びます。
A7: 04_月間表 | B7: 日付を縦に並べた一覧。空室数や食数の根拠を数字で確認したいときに使います。カレンダーと帯表はこのシートを引いているので、内容は必ず一致します。
A8: 05_空室照会 | B8: 「この期間空いてますか」と電話で聞かれたとき用。日付を2つ入れるだけです。
A9: 06_食数表 | B9: 厨房へ渡す日別の朝・昼・夕の食数。★個別の調整は 02_カレンダー の下部で日付ごとに入れます。
A10: 07_月次集計 | B10: 上司報告・請求突合用。★稼働率・区分別・利用者別が出ます。期間を空欄にしておけば対象月に連動し、日付を入れれば年度など任意の期間で集計できます。
A11: 08_支給量管理 | B11: 受給者証の月あたり上限に対する残日数。
A12: 09_FAX空き表 | B12: ★このまま印刷してFAX送信できる1枚ものの用紙です。送信票と空き状況カレンダーが一体になっており、送信先・送信元・挨拶文・凡例・注意書き・連絡事項欄まで入っています。利用者名は載りません。A4縦1枚に収まるよう設定済みです。
A13: ★ 日付の入れ方（年月は最初の1回だけ）
A14: 年月は1回だけ | B14: 01_予約入力 の「年月」列に、最初の行で 2026/8 のように一度だけ入れてください。以降の行は空欄のままでかまいません。上の行の年月を自動で引き継ぎます。
A15: あとは日にちだけ | B15: 「入所(日)」「退所(日)」には日にちの数字（1〜31）だけを入れます。その右の「入所日(自動)」「退所予定日(自動)」に、年月と組み合わせた日付が自動で入ります。
A16: 月をまたぐとき | B16: 退所の日にちが入所より前になる場合は、自動で「翌月のその日」と判断します（例: 入所31 → 退所1 なら翌月1日）。
A17: 月が変わったら | B17: 新しい月の最初の行に、その月の年月（例 2026/9）を入れてください。そこから下が新しい月になります。
A18: 直接日付でも可 | B18: 1か月を超える滞在など、特別なときは日にち欄に日付そのもの（2026/9/3 など）を入れても動きます。
A19: ★時刻は「時」だけ | B19: 「入所(時)」「退所(時)」には時の数字だけを入れてください（16 と入れれば 16:00）。9時なら 9 だけで 09:00 になります。分は入力不要です。
A20: 分が必要なとき | B20: 16:30 のように「時:分」で入れれば、そのまま分まで表示されます。
A21: 時刻は空欄でも可 | B21: 時刻を入れなくても予約は成立します。カレンダーに時刻が出ないだけです。
A22: ★注意 | B22: 行の並べ替え（ソート）はしないでください。年月の引き継ぎが崩れます。絞り込みたいときは、並べ替えではなくフィルタを使ってください。
A23: はじめに設定すること
A24: ① M_施設設定 | B24: 施設名・棟・標準の入所/退所時刻・住所・TEL/FAX を入れます。
A25: ② M_部屋 | B25: 部屋名を1行1室で登録します。★ここの行数が、そのまま定員（部屋数）になります。
A26: ③ 利用者マスタ | B26: 氏名と支給量（受給者証の月あたり上限日数）。支給量が空欄の方は残日数を管理しません。
A27: ⑤ M_FAX送付先 | B27: 相談支援事業所などFAXの送り先を登録します。09_FAX空き表 の宛先が一覧から選べるようになり、番号の打ち間違いによる誤送信を防げます。
A28: ④ M_区分・M_送迎 | B28: 区分（SS・無料・契約など）と、その区分を支給量に数えるかどうか。★区分名はカレンダーの色分けに使います。M_区分 の上から4つまでが色に対応します。
A29: ★ 部屋数が施設ごとに違う場合（1室の施設と2室の施設）
A30: 同じファイルで使えます | B30: 1室の施設は M_部屋 に1行だけ、2室の施設は2行だけ登録してください。定員・空室数・空き記号（○△×）は全て M_部屋 の行数から計算しているので、シートも数式も一切変えずに両方に対応します。最大4室まで。
A31: 使わない部屋の行を隠す | B31: 02_カレンダー は各週に「部屋1〜部屋4」の4行があります。1〜2室の施設では、使わない部屋の行（部屋名が空欄の行）をまとめて選択し、右クリック→非表示 にしてください。6週ぶんまとめて選べます。03_帯表・04_月間表 も同様に列を非表示にできます。
A32: 部屋を減らしたとき | B32: 2室から1室に変更したのに古い予約が「部屋2」のまま残っていると、01_予約入力 のS列に「⚠部屋が未登録」と赤で出ます。その予約の部屋を選び直してください。
A33: 1室のときの表示 | B33: 1室の施設では「△（残りわずか）」は構造上発生せず、必ず ○ か × になります。
A34: ★ファイルは施設ごとに分ける | B34: このファイルを施設の数だけコピーして「施設A_管理台帳.xlsx」「施設B_管理台帳.xlsx」のように分けてください。1つのファイルに複数施設を混ぜると、定員が施設ごとに違うため空き判定が成立せず、全ての集計に施設の絞り込みが必要になって必ず崩れます。
A35: ★ 食事の決め方（3段階）
A36: ① 標準（何もしない） | B36: 日帰り=昼のみ ／ 初日=夕 ／ 中日=朝昼夕 ／ 最終日=朝。ほとんどの予約はこれで足ります。
A37: ② 予約ごとに決める | B37: 01_予約入力 の「朝食」「昼食」「夕食」列で選びます。空欄=標準、○=その滞在の全ての利用日で出す、×=その滞在では出さない。「この方は毎日昼食もつける」「この方は朝食なし」といった決め方に使います。
A38: ③ 特定の日だけ直す | B38: 02_カレンダー 下部の「食事の個別調整」に日付と食数を入れます。★①②より優先されます。「この日だけ来客で1食多い」といった例外に使います。
A39: 反映先 | B39: どれで決めても、02_カレンダー の食事行と 06_食数表 に自動で反映されます。
A40: ★ 食事をカレンダーで見る・直す
A41: いつもは自動 | B41: 各週のいちばん下の「食事」行に、その日の 朝○ 昼○ 夕○ が自動で出ます。予約ごとの指定（01_予約入力 の朝食・昼食・夕食）もここに反映されます。
...

Sheet 01_予約入力
A1: 予約入力（1滞在 = 1行）
A2: ★日付は「年月」を最初の行に一度だけ入れれば、あとは日にちの数字だけ。時刻も「時」の数字だけ（16 → 16:00）。食事は空欄なら標準どおりです。黄色の列だけ入力します。Y列・Z列が赤くなったら、その行を直してください。
A4: 予約ID | B4: 氏名 | C4: 区分 | D4: 部屋 | E4: 年月 (最初の行だけ) | F4: 入所 (日) | G4: 入所日 (自動) | H4: 入所 (時) | I4: 退所 (日) | J4: 退所予定日 (自動) | K4: 退所 (時) | L4: 朝食 | M4: 昼食 | N4: 夕食 | O4: 利用日数 | P4: 宿泊数 | Q4: 予約状態 | R4: 送迎 | S4: 送迎方法 | T4: 送迎場所・時間帯 | U4: 外部サービス | V4: 備考 | W4: 更新日 | X4: 更新者 | Y4: ⚠重複・部屋チェック | Z4: ⚠支給量チェック | AA4: 支給量対象日数 | AB4: 作業:実効年月 | AC4: 作業:並び順 | AD4: 作業:入所時刻 | AE4: 作業:退所時刻 | AF4: 作業:入所日数値 | AG4: 作業:退所日数値
A5: =IF($G5="","","SS-"&TEXT(ROW()-4,"0000")) | B5: ◎◎様 | C5: SS | D5: １Ｆ | E5: 46235 | F5: 1 | G5: =IF($F5="","",IF($F5>31,$F5,IF($AB5="","",DATE(YEAR($AB5),MONTH($AB5),$F5)))) | H5: 16 | I5: 2 | J5: =IF($I5="","",IF($I5>31,$I5,IF($G5="","",IF(DATE(YEAR($G5),MONTH($G5),$I5)>=$G5,DATE(YEAR($G5),MONTH($G5),$I5),DATE(YEAR($G5),MONTH($G5)+1,$I5))))) | K5: 9 | O5: =IF(OR($G5="",$J5=""),"",$J5-$G5+1) | P5: =IF(OR($G5="",$J5=""),"",$J5-$G5) | Q5: 確定 | R5: あり | S5: 施設車 | T5: 自宅前 16:00 | Y5: =IF($G5="","",IF($D5="","⚠部屋が未選択",IF(COUNTIF('M_部屋'!$A$4:$A$20,$D5)=0,"⚠部屋が未登録",IF(OR($J5="",$Q5="キャンセル"),"",IF(SUMPRODUCT(($D$5:$D$404=$D5)*($G$5:$G$404<>"")*($J$5:$J$404<>"")*($Q$5:$Q$404<>"キャンセル")*($G$5:$G$404<$J5)*($J$5:$J$404>$G5))>1,"⚠重複",""))))) | Z5: =IF(OR($B5="",$G5=""),"",IF(SUMPRODUCT(('利用者マスタ'!$A$4:$A$60=$B5)*('利用者マスタ'!$B$4:$B$60<>""))=0,"",IF(SUMIFS($AA$5:$AA$404,$B$5:$B$404,$B5,$G$5:$G$404,">="&DATE(YEAR($G5),MONTH($G5),1),$G$5:$G$404,"<="&EOMONTH($G5,0))>SUMIFS('利用者マスタ'!$B$4:$B$60,'利用者マスタ'!$A$4:$A$60,$B5),"⚠支給量超過",""))) | AA5: =IF(OR($G5="",$J5="",$Q5="キャンセル"),0,IF(IFERROR(INDEX('M_区分'!$B$4:$B$20,MATCH($C5,'M_区分'!$A$4:$A$20,0)),"○")="○",$J5-$G5+1,0)) | AB5: =IF($E5<>"",$E5,"") | AC5: =IF(OR($G5="",$J5=""),"",IF(AND($G5<=EOMONTH('02_カレンダー'!$B$4,0),$J5>='02_カレンダー'!$B$4),$G5*10000+ROW(),"")) | AD5: =IF($H5="","",IF(ISNUMBER($H5),IF(AND($H5=INT($H5),$H5>=0,$H5<=24),TEXT(INT($H5),"00")&":00",TEXT($H5,"hh:mm")),$H5)) | AE5: =IF($K5="","",IF(ISNUMBER($K5),IF(AND($K5=INT($K5),$K5>=0,$K5<=24),TEXT(INT($K5),"00")&":00",TEXT($K5,"hh:mm")),$K5)) | AF5: =IF($G5="",0,$G5) | AG5: =IF($J5="",0,$J5)
A6: =IF($G6="","","SS-"&TEXT(ROW()-4,"0000")) | B6: 木村様 | C6: SS | D6: １Ｆ | F6: 5 | G6: =IF($F6="","",IF($F6>31,$F6,IF($AB6="","",DATE(YEAR($AB6),MONTH($AB6),$F6)))) | H6: 16:30 | I6: 7 | J6: =IF($I6="","",IF($I6>31,$I6,IF($G6="","",IF(DATE(YEAR($G6),MONTH($G6),$I6)>=$G6,DATE(YEAR($G6),MONTH($G6),$I6),DATE(YEAR($G6),MONTH($G6)+1,$I6))))) | K6: 9 | O6: =IF(OR($G6="",$J6=""),"",$J6-$G6+1) | P6: =IF(OR($G6="",$J6=""),"",$J6-$G6) | Q6: 確定 | R6: なし | Y6: =IF($G6="","",IF($D6="","⚠部屋が未選択",IF(COUNTIF('M_部屋'!$A$4:$A$20,$D6)=0,"⚠部屋が未登録",IF(OR($J6="",$Q6="キャンセル"),"",IF(SUMPRODUCT(($D$5:$D$404=$D6)*($G$5:$G$404<>"")*($J$5:$J$404<>"")*($Q$5:$Q$404<>"キャンセル")*($G$5:$G$404<$J6)*($J$5:$J$404>$G6))>1,"⚠重複",""))))) | Z6: =IF(OR($B6="",$G6=""),"",IF(SUMPRODUCT(('利用者マスタ'!$A$4:$A$60=$B6)*('利用者マスタ'!$B$4:$B$60<>""))=0,"",IF(SUMIFS($AA$5:$AA$404,$B$5:$B$404,$B6,$G$5:$G$404,">="&DATE(YEAR($G6),MONTH($G6),1),$G$5:$G$404,"<="&EOMONTH($G6,0))>SUMIFS('利用者マスタ'!$B$4:$B$60,'利用者マスタ'!$A$4:$A$60,$B6),"⚠支給量超過",""))) | AA6: =IF(OR($G6="",$J6="",$Q6="キャンセル"),0,IF(IFERROR(INDEX('M_区分'!$B$4:$B$20,MATCH($C6,'M_区分'!$A$4:$A$20,0)),"○")="○",$J6-$G6+1,0)) | AB6: =IF($E6<>"",$E6,$AB5) | AC6: =IF(OR($G6="",$J6=""),"",IF(AND($G6<=EOMONTH('02_カレンダー'!$B$4,0),$J6>='02_カレンダー'!$B$4),$G6*10000+ROW(),"")) | AD6: =IF($H6="","",IF(ISNUMBER($H6),IF(AND($H6=INT($H6),$H6>=0,$H6<=24),TEXT(INT($H6),"00")&":00",TEXT($H6,"hh:mm")),$H6)) | AE6: =IF($K6="","",IF(ISNUMBER($K6),IF(AND($K6=INT($K6),$K6>=0,$K6<=24),TEXT(INT($K6),"00")&":00",TEXT($K6,"hh:mm")),$K6)) | AF6: =IF($G6="",0,$G6) | AG6: =IF($J6="",0,$J6)
A7: =IF($G7="","","SS-"&TEXT(ROW()-4,"0000")) | B7: ◎◎様 | C7: SS | D7: １Ｆ | F7: 8 | G7: =IF($F7="","",IF($F7>31,$F7,IF($AB7="","",DATE(YEAR($AB7),MONTH($AB7),$F7)))) | H7: 10 | I7: 8 | J7: =IF($I7="","",IF($I7>31,$I7,IF($G7="","",IF(DATE(YEAR($G7),MONTH($G7),$I7)>=$G7,DATE(YEAR($G7),MONTH($G7),$I7),DATE(YEAR($G7),MONTH($G7)+1,$I7))))) | K7: 16 | O7: =IF(OR($G7="",$J7=""),"",$J7-$G7+1) | P7: =IF(OR($G7="",$J7=""),"",$J7-$G7) | Q7: 確定 | R7: あり | S7: 家族送迎 | V7: 日帰り（体験利用） | Y7: =IF($G7="","",IF($D7="","⚠部屋が未選択",IF(COUNTIF('M_部屋'!$A$4:$A$20,$D7)=0,"⚠部屋が未登録",IF(OR($J7="",$Q7="キャンセル"),"",IF(SUMPRODUCT(($D$5:$D$404=$D7)*($G$5:$G$404<>"")*($J$5:$J$404<>"")*($Q$5:$Q$404<>"キャンセル")*($G$5:$G$404<$J7)*($J$5:$J$404>$G7))>1,"⚠重複",""))))) | Z7: =IF(OR($B7="",$G7=""),"",IF(SUMPRODUCT(('利用者マスタ'!$A$4:$A$60=$B7)*('利用者マスタ'!$B$4:$B$60<>""))=0,"",IF(SUMIFS($AA$5:$AA$404,$B$5:$B$404,$B7,$G$5:$G$404,">="&DATE(YEAR($G7),MONTH($G7),1),$G$5:$G$404,"<="&EOMONTH($G7,0))>SUMIFS('利用者マスタ'!$B$4:$B$60,'利用者マスタ'!$A$4:$A$60,$B7),"⚠支給量超過",""))) | AA7: =IF(OR($G7="",$J7="",$Q7="キャンセル"),0,IF(IFERROR(INDEX('M_区分'!$B$4:$B$20,MATCH($C7,'M_区分'!$A$4:$A$20,0)),"○")="○",$J7-$G7+1,0)) | AB7: =IF($E7<>"",$E7,$AB6) | AC7: =IF(OR($G7="",$J7=""),"",IF(AND($G7<=EOMONTH('02_カレンダー'!$B$4,0),$J7>='02_カレンダー'!$B$4),$G7*10000+ROW(),"")) | AD7: =IF($H7="","",IF(ISNUMBER($H7),IF(AND($H7=INT($H7),$H7>=0,$H7<=24),TEXT(INT($H7),"00")&":00",TEXT($H7,"hh:mm")),$H7)) | AE7: =IF($K7="","",IF(ISNUMBER($K7),IF(AND($K7=INT($K7),$K7>=0,$K7<=24),TEXT(INT($K7),"00")&":00",TEXT($K7,"hh:mm")),$K7)) | AF7: =IF($G7="",0,$G7) | AG7: =IF($J7="",0,$J7)
A8: =IF($G8="","","SS-"&TEXT(ROW()-4,"0000")) | B8: 小澤様 | C8: SS | D8: １Ｆ | F8: 14 | G8: =IF($F8="","",IF($F8>31,$F8,IF($AB8="","",DATE(YEAR($AB8),MONTH($AB8),$F8)))) | H8: 16 | I8: 16 | J8: =IF($I8="","",IF($I8>31,$I8,IF($G8="","",IF(DATE(YEAR($G8),MONTH($G8),$I8)>=$G8,DATE(YEAR($G8),MONTH($G8),$I8),DATE(YEAR($G8),MONTH($G8)+1,$I8))))) | K8: 9 | O8: =IF(OR($G8="",$J8=""),"",$J8-$G8+1) | P8: =IF(OR($G8="",$J8=""),"",$J8-$G8) | Q8: 確定 | R8: 調整中 | Y8: =IF($G8="","",IF($D8="","⚠部屋が未選択",IF(COUNTIF('M_部屋'!$A$4:$A$20,$D8)=0,"⚠部屋が未登録",IF(OR($J8="",$Q8="キャンセル"),"",IF(SUMPRODUCT(($D$5:$D$404=$D8)*($G$5:$G$404<>"")*($J$5:$J$404<>"")*($Q$5:$Q$404<>"キャンセル")*($G$5:$G$404<$J8)*($J$5:$J$404>$G8))>1,"⚠重複",""))))) | Z8: =IF(OR($B8="",$G8=""),"",IF(SUMPRODUCT(('利用者マスタ'!$A$4:$A$60=$B8)*('利用者マスタ'!$B$4:$B$60<>""))=0,"",IF(SUMIFS($AA$5:$AA$404,$B$5:$B$404,$B8,$G$5:$G$404,">="&DATE(YEAR($G8),MONTH($G8),1),$G$5:$G$404,"<="&EOMONTH($G8,0))>SUMIFS('利用者マスタ'!$B$4:$B$60,'利用者マスタ'!$A$4:$A$60,$B8),"⚠支給量超過",""))) | AA8: =IF(OR($G8="",$J8="",$Q8="キャンセル"),0,IF(IFERROR(INDEX('M_区分'!$B$4:$B$20,MATCH($C8,'M_区分'!$A$4:$A$20,0)),"○")="○",$J8-$G8+1,0)) | AB8: =IF($E8<>"",$E8,$AB7) | AC8: =IF(OR($G8="",$J8=""),"",IF(AND($G8<=EOMONTH('02_カレンダー'!$B$4,0),$J8>='02_カレンダー'!$B$4),$G8*10000+ROW(),"")) | AD8: =IF($H8="","",IF(ISNUMBER($H8),IF(AND($H8=INT($H8),$H8>=0,$H8<=24),TEXT(INT($H8),"00")&":00",TEXT($H8,"hh:mm")),$H8)) | AE8: =IF($K8="","",IF(ISNUMBER($K8),IF(AND($K8=INT($K8),$K8>=0,$K8<=24),TEXT(INT($K8),"00")&":00",TEXT($K8,"hh:mm")),$K8)) | AF8: =IF($G8="",0,$G8) | AG8: =IF($J8="",0,$J8)
A9: =IF($G9="","","SS-"&TEXT(ROW()-4,"0000")) | B9: 木村様 | C9: SS | D9: １Ｆ | F9: 19 | G9: =IF($F9="","",IF($F9>31,$F9,IF($AB9="","",DATE(YEAR($AB9),MONTH($AB9),$F9)))) | H9: 15 | I9: 21 | J9: =IF($I9="","",IF($I9>31,$I9,IF($G9="","",IF(DATE(YEAR($G9),MONTH($G9),$I9)>=$G9,DATE(YEAR($G9),MONTH($G9),$I9),DATE(YEAR($G9),MONTH($G9)+1,$I9))))) | O9: =IF(OR($G9="",$J9=""),"",$J9-$G9+1) | P9: =IF(OR($G9="",$J9=""),"",$J9-$G9) | Y9: =IF($G9="","",IF($D9="","⚠部屋が未選択",IF(COUNTIF('M_部屋'!$A$4:$A$20,$D9)=0,"⚠部屋が未登録",IF(OR($J9="",$Q9="キャンセル"),"",IF(SUMPRODUCT(($D$5:$D$404=$D9)*($G$5:$G$404<>"")*($J$5:$J$404<>"")*($Q$5:$Q$404<>"キャンセル")*($G$5:$G$404<$J9)*($J$5:$J$404>$G9))>1,"⚠重複",""))))) | Z9: =IF(OR($B9="",$G9=""),"",IF(SUMPRODUCT(('利用者マスタ'!$A$4:$A$60=$B9)*('利用者マスタ'!$B$4:$B$60<>""))=0,"",IF(SUMIFS($AA$5:$AA$404,$B$5:$B$404,$B9,$G$5:$G$404,">="&DATE(YEAR($G9),MONTH($G9),1),$G$5:$G$404,"<="&EOMONTH($G9,0))>SUMIFS('利用者マスタ'!$B$4:$B$60,'利用者マスタ'!$A$4:$A$60,$B9),"⚠支給量超過",""))) | AA9: =IF(OR($G9="",$J9="",$Q9="キャンセル"),0,IF(IFERROR(INDEX('M_区分'!$B$4:$B$20,MATCH($C9,'M_区分'!$A$4:$A$20,0)),"○")="○",$J9-$G9+1,0)) | AB9: =IF($E9<>"",$E9,$AB8) | AC9: =IF(OR($G9="",$J9=""),"",IF(AND($G9<=EOMONTH('02_カレンダー'!$B$4,0),$J9>='02_カレンダー'!$B$4),$G9*10000+ROW(),"")) | AD9: =IF($H9="","",IF(ISNUMBER($H9),IF(AND($H9=INT($H9),$H9>=0,$H9<=24),TEXT(INT($H9),"00")&":00",TEXT($H9,"hh:mm")),$H9)) | AE9: =IF($K9="","",IF(ISNUMBER($K9),IF(AND($K9=INT($K9),$K9>=0,$K9<=24),TEXT(INT($K9),"00")&":00",TEXT($K9,"hh:mm")),$K9)) | AF9: =IF($G9="",0,$G9) | AG9: =IF($J9="",0,$J9)
A10: =IF($G10="","","SS-"&TEXT(ROW()-4,"0000")) | B10: 伊藤メイ様 | C10: SS | D10: １Ｆ | F10: 21 | G10: =IF($F10="","",IF($F10>31,$F10,IF($AB10="","",DATE(YEAR($AB10),MONTH($AB10),$F10)))) | H10: 15 | I10: 22 | J10: =IF($I10="","",IF($I10>31,$I10,IF($G10="","",IF(DATE(YEAR($G10),MONTH($G10),$I10)>=$G10,DATE(YEAR($G10),MONTH($G10),$I10),DATE(YEAR($G10),MONTH($G10)+1,$I10))))) | O10: =IF(OR($G10="",$J10=""),"",$J10-$G10+1) | P10: =IF(OR($G10="",$J10=""),"",$J10-$G10) | Y10: =IF($G10="","",IF($D10="","⚠部屋が未選択",IF(COUNTIF('M_部屋'!$A$4:$A$20,$D10)=0,"⚠部屋が未登録",IF(OR($J10="",$Q10="キャンセル"),"",IF(SUMPRODUCT(($D$5:$D$404=$D10)*($G$5:$G$404<>"")*($J$5:$J$404<>"")*($Q$5:$Q$404<>"キャンセル")*($G$5:$G$404<$J10)*($J$5:$J$404>$G10))>1,"⚠重複",""))))) | Z10: =IF(OR($B10="",$G10=""),"",IF(SUMPRODUCT(('利用者マスタ'!$A$4:$A$60=$B10)*('利用者マスタ'!$B$4:$B$60<>""))=0,"",IF(SUMIFS($AA$5:$AA$404,$B$5:$B$404,$B10,$G$5:$G$404,">="&DATE(YEAR($G10),MONTH($G10),1),$G$5:$G$404,"<="&EOMONTH($G10,0))>SUMIFS('利用者マスタ'!$B$4:$B$60,'利用者マスタ'!$A$4:$A$60,$B10),"⚠支給量超過",""))) | AA10: =IF(OR($G10="",$J10="",$Q10="キャンセル"),0,IF(IFERROR(INDEX('M_区分'!$B$4:$B$20,MATCH($C10,'M_区分'!$A$4:$A$20,0)),"○")="○",$J10-$G10+1,0)) | AB10: =IF($E10<>"",$E10,$AB9) | AC10: =IF(OR($G10="",$J10=""),"",IF(AND($G10<=EOMONTH('02_カレンダー'!$B$4,0),$J10>='02_カレンダー'!$B$4),$G10*10000+ROW(),"")) | AD10: =IF($H10="","",IF(ISNUMBER($H10),IF(AND($H10=INT($H10),$H10>=0,$H10<=24),TEXT(INT($H10),"00")&":00",TEXT($H10,"hh:mm")),$H10)) | AE10: =IF($K10="","",IF(ISNUMBER($K10),IF(AND($K10=INT($K10),$K10>=0,$K10<=24),TEXT(INT($K10),"00")&":00",TEXT($K10,"hh:mm")),$K10)) | AF10: =IF($G10="",0,$G10) | AG10: =IF($J10="",0,$J10)
A11: =IF($G11="","","SS-"&TEXT(ROW()-4,"0000")) | B11: 小澤様 | C11: SS | D11: １Ｆ | F11: 22 | G11: =IF($F11="","",IF($F11>31,$F11,IF($AB11="","",DATE(YEAR($AB11),MONTH($AB11),$F11)))) | H11: 15 | I11: 23 | J11: =IF($I11="","",IF($I11>31,$I11,IF($G11="","",IF(DATE(YEAR($G11),MONTH($G11),$I11)>=$G11,DATE(YEAR($G11),MONTH($G11),$I11),DATE(YEAR($G11),MONTH($G11)+1,$I11))))) | O11: =IF(OR($G11="",$J11=""),"",$J11-$G11+1) | P11: =IF(OR($G11="",$J11=""),"",$J11-$G11) | Y11: =IF($G11="","",IF($D11="","⚠部屋が未選択",IF(COUNTIF('M_部屋'!$A$4:$A$20,$D11)=0,"⚠部屋が未登録",IF(OR($J11="",$Q11="キャンセル"),"",IF(SUMPRODUCT(($D$5:$D$404=$D11)*($G$5:$G$404<>"")*($J$5:$J$404<>"")*($Q$5:$Q$404<>"キャンセル")*($G$5:$G$404<$J11)*($J$5:$J$404>$G11))>1,"⚠重複",""))))) | Z11: =IF(OR($B11="",$G11=""),"",IF(SUMPRODUCT(('利用者マスタ'!$A$4:$A$60=$B11)*('利用者マスタ'!$B$4:$B$60<>""))=0,"",IF(SUMIFS($AA$5:$AA$404,$B$5:$B$404,$B11,$G$5:$G$404,">="&DATE(YEAR($G11),MONTH($G11),1),$G$5:$G$404,"<="&EOMONTH($G11,0))>SUMIFS('利用者マスタ'!$B$4:$B$60,'利用者マスタ'!$A$4:$A$60,$B11),"⚠支給量超過",""))) | AA11: =IF(OR($G11="",$J11="",$Q11="キャンセル"),0,IF(IFERROR(INDEX('M_区分'!$B$4:$B$20,MATCH($C11,'M_区分'!$A$4:$A$20,0)),"○")="○",$J11-$G11+1,0)) | AB11: =IF($E11<>"",$E11,$AB10) | AC11: =IF(OR($G11="",$J11=""),"",IF(AND($G11<=EOMONTH('02_カレンダー'!$B$4,0),$J11>='02_カレンダー'!$B$4),$G11*10000+ROW(),"")) | AD11: =IF($H11="","",IF(ISNUMBER($H11),IF(AND($H11=INT($H11),$H11>=0,$H11<=24),TEXT(INT($H11),"00")&":00",TEXT($H11,"hh:mm")),$H11)) | AE11: =IF($K11="","",IF(ISNUMBER($K11),IF(AND($K11=INT($K11),$K11>=0,$K11<=24),TEXT(INT($K11),"00")&":00",TEXT($K11,"hh:mm")),$K11)) | AF11: =IF($G11="",0,$G11) | AG11: =IF($J11="",0,$J11)
A12: =IF($G12="","","SS-"&TEXT(ROW()-4,"0000")) | B12: 小林様 | C12: SS | D12: １Ｆ | F12: 29 | G12: =IF($F12="","",IF($F12>31,$F12,IF($AB12="","",DATE(YEAR($AB12),MONTH($AB12),$F12)))) | H12: 15 | I12: 30 | J12: =IF($I12="","",IF($I12>31,$I12,IF($G12="","",IF(DATE(YEAR($G12),MONTH($G12),$I12)>=$G12,DATE(YEAR($G12),MONTH($G12),$I12),DATE(YEAR($G12),MONTH($G12)+1,$I12))))) | O12: =IF(OR($G12="",$J12=""),"",$J12-$G12+1) | P12: =IF(OR($G12="",$J12=""),"",$J12-$G12) | Y12: =IF($G12="","",IF($D12="","⚠部屋が未選択",IF(COUNTIF('M_部屋'!$A$4:$A$20,$D12)=0,"⚠部屋が未登録",IF(OR($J12="",$Q12="キャンセル"),"",IF(SUMPRODUCT(($D$5:$D$404=$D12)*($G$5:$G$404<>"")*($J$5:$J$404<>"")*($Q$5:$Q$404<>"キャンセル")*($G$5:$G$404<$J12)*($J$5:$J$404>$G12))>1,"⚠重複",""))))) | Z12: =IF(OR($B12="",$G12=""),"",IF(SUMPRODUCT(('利用者マスタ'!$A$4:$A$60=$B12)*('利用者マスタ'!$B$4:$B$60<>""))=0,"",IF(SUMIFS($AA$5:$AA$404,$B$5:$B$404,$B12,$G$5:$G$404,">="&DATE(YEAR($G12),MONTH($G12),1),$G$5:$G$404,"<="&EOMONTH($G12,0))>SUMIFS('利用者マスタ'!$B$4:$B$60,'利用者マスタ'!$A$4:$A$60,$B12),"⚠支給量超過",""))) | AA12: =IF(OR($G12="",$J12="",$Q12="キャンセル"),0,IF(IFERROR(INDEX('M_区分'!$B$4:$B$20,MATCH($C12,'M_区分'!$A$4:$A$20,0)),"○")="○",$J12-$G12+1,0)) | AB12: =IF($E12<>"",$E12,$AB11) | AC12: =IF(OR($G12="",$J12=""),"",IF(AND($G12<=EOMONTH('02_カレンダー'!$B$4,0),$J12>='02_カレンダー'!$B$4),$G12*10000+ROW(),"")) | AD12: =IF($H12="","",IF(ISNUMBER($H12),IF(AND($H12=INT($H12),$H12>=0,$H12<=24),TEXT(INT($H12),"00")&":00",TEXT($H12,"hh:mm")),$H12)) | AE12: =IF($K12="","",IF(ISNUMBER($K12),IF(AND($K12=INT($K12),$K12>=0,$K12<=24),TEXT(INT($K12),"00")&":00",TEXT($K12,"hh:mm")),$K12)) | AF12: =IF($G12="",0,$G12) | AG12: =IF($J12="",0,$J12)
A13: =IF($G13="","","SS-"&TEXT(ROW()-4,"0000")) | B13: 木村様 | C13: SS | D13: １Ｆ | F13: 31 | G13: =IF($F13="","",IF($F13>31,$F13,IF($AB13="","",DATE(YEAR($AB13),MONTH($AB13),$F13)))) | H13: 15 | I13: 1 | J13: =IF($I13="","",IF($I13>31,$I13,IF($G13="","",IF(DATE(YEAR($G13),MONTH($G13),$I13)>=$G13,DATE(YEAR($G13),MONTH($G13),$I13),DATE(YEAR($G13),MONTH($G13)+1,$I13))))) | O13: =IF(OR($G13="",$J13=""),"",$J13-$G13+1) | P13: =IF(OR($G13="",$J13=""),"",$J13-$G13) | Y13: =IF($G13="","",IF($D13="","⚠部屋が未選択",IF(COUNTIF('M_部屋'!$A$4:$A$20,$D13)=0,"⚠部屋が未登録",IF(OR($J13="",$Q13="キャンセル"),"",IF(SUMPRODUCT(($D$5:$D$404=$D13)*($G$5:$G$404<>"")*($J$5:$J$404<>"")*($Q$5:$Q$404<>"キャンセル")*($G$5:$G$404<$J13)*($J$5:$J$404>$G13))>1,"⚠重複",""))))) | Z13: =IF(OR($B13="",$G13=""),"",IF(SUMPRODUCT(('利用者マスタ'!$A$4:$A$60=$B13)*('利用者マスタ'!$B$4:$B$60<>""))=0,"",IF(SUMIFS($AA$5:$AA$404,$B$5:$B$404,$B13,$G$5:$G$404,">="&DATE(YEAR($G13),MONTH($G13),1),$G$5:$G$404,"<="&EOMONTH($G13,0))>SUMIFS('利用者マスタ'!$B$4:$B$60,'利用者マスタ'!$A$4:$A$60,$B13),"⚠支給量超過",""))) | AA13: =IF(OR($G13="",$J13="",$Q13="キャンセル"),0,IF(IFERROR(INDEX('M_区分'!$B$4:$B$20,MATCH($C13,'M_区分'!$A$4:$A$20,0)),"○")="○",$J13-$G13+1,0)) | AB13: =IF($E13<>"",$E13,$AB12) | AC13: =IF(OR($G13="",$J13=""),"",IF(AND($G13<=EOMONTH('02_カレンダー'!$B$4,0),$J13>='02_カレンダー'!$B$4),$G13*10000+ROW(),"")) | AD13: =IF($H13="","",IF(ISNUMBER($H13),IF(AND($H13=INT($H13),$H13>=0,$H13<=24),TEXT(INT($H13),"00")&":00",TEXT($H13,"hh:mm")),$H13)) | AE13: =IF($K13="","",IF(ISNUMBER($K13),IF(AND($K13=INT($K13),$K13>=0,$K13<=24),TEXT(INT($K13),"00")&":00",TEXT($K13,"hh:mm")),$K13)) | AF13: =IF($G13="",0,$G13) | AG13: =IF($J13="",0,$J13)
A14: =IF($G14="","","SS-"&TEXT(ROW()-4,"0000")) | G14: =IF($F14="","",IF($F14>31,$F14,IF($AB14="","",DATE(YEAR($AB14),MONTH($AB14),$F14)))) | J14: =IF($I14="","",IF($I14>31,$I14,IF($G14="","",IF(DATE(YEAR($G14),MONTH($G14),$I14)>=$G14,DATE(YEAR($G14),MONTH($G14),$I14),DATE(YEAR($G14),MONTH($G14)+1,$I14))))) | O14: =IF(OR($G14="",$J14=""),"",$J14-$G14+1) | P14: =IF(OR($G14="",$J14=""),"",$J14-$G14) | Y14: =IF($G14="","",IF($D14="","⚠部屋が未選択",IF(COUNTIF('M_部屋'!$A$4:$A$20,$D14)=0,"⚠部屋が未登録",IF(OR($J14="",$Q14="キャンセル"),"",IF(SUMPRODUCT(($D$5:$D$404=$D14)*($G$5:$G$404<>"")*($J$5:$J$404<>"")*($Q$5:$Q$404<>"キャンセル")*($G$5:$G$404<$J14)*($J$5:$J$404>$G14))>1,"⚠重複",""))))) | Z14: =IF(OR($B14="",$G14=""),"",IF(SUMPRODUCT(('利用者マスタ'!$A$4:$A$60=$B14)*('利用者マスタ'!$B$4:$B$60<>""))=0,"",IF(SUMIFS($AA$5:$AA$404,$B$5:$B$404,$B14,$G$5:$G$404,">="&DATE(YEAR($G14),MONTH($G14),1),$G$5:$G$404,"<="&EOMONTH($G14,0))>SUMIFS('利用者マスタ'!$B$4:$B$60,'利用者マスタ'!$A$4:$A$60,$B14),"⚠支給量超過",""))) | AA14: =IF(OR($G14="",$J14="",$Q14="キャンセル"),0,IF(IFERROR(INDEX('M_区分'!$B$4:$B$20,MATCH($C14,'M_区分'!$A$4:$A$20,0)),"○")="○",$J14-$G14+1,0)) | AB14: =IF($E14<>"",$E14,$AB13) | AC14: =IF(OR($G14="",$J14=""),"",IF(AND($G14<=EOMONTH('02_カレンダー'!$B$4,0),$J14>='02_カレンダー'!$B$4),$G14*10000+ROW(),"")) | AD14: =IF($H14="","",IF(ISNUMBER($H14),IF(AND($H14=INT($H14),$H14>=0,$H14<=24),TEXT(INT($H14),"00")&":00",TEXT($H14,"hh:mm")),$H14)) | AE14: =IF($K14="","",IF(ISNUMBER($K14),IF(AND($K14=INT($K14),$K14>=0,$K14<=24),TEXT(INT($K14),"00")&":00",TEXT($K14,"hh:mm")),$K14)) | AF14: =IF($G14="",0,$G14) | AG14: =IF($J14="",0,$J14)
A15: =IF($G15="","","SS-"&TEXT(ROW()-4,"0000")) | G15: =IF($F15="","",IF($F15>31,$F15,IF($AB15="","",DATE(YEAR($AB15),MONTH($AB15),$F15)))) | J15: =IF($I15="","",IF($I15>31,$I15,IF($G15="","",IF(DATE(YEAR($G15),MONTH($G15),$I15)>=$G15,DATE(YEAR($G15),MONTH($G15),$I15),DATE(YEAR($G15),MONTH($G15)+1,$I15))))) | O15: =IF(OR($G15="",$J15=""),"",$J15-$G15+1) | P15: =IF(OR($G15="",$J15=""),"",$J15-$G15) | Y15: =IF($G15="","",IF($D15="","⚠部屋が未選択",IF(COUNTIF('M_部屋'!$A$4:$A$20,$D15)=0,"⚠部屋が未登録",IF(OR($J15="",$Q15="キャンセル"),"",IF(SUMPRODUCT(($D$5:$D$404=$D15)*($G$5:$G$404<>"")*($J$5:$J$404<>"")*($Q$5:$Q$404<>"キャンセル")*($G$5:$G$404<$J15)*($J$5:$J$404>$G15))>1,"⚠重複",""))))) | Z15: =IF(OR($B15="",$G15=""),"",IF(SUMPRODUCT(('利用者マスタ'!$A$4:$A$60=$B15)*('利用者マスタ'!$B$4:$B$60<>""))=0,"",IF(SUMIFS($AA$5:$AA$404,$B$5:$B$404,$B15,$G$5:$G$404,">="&DATE(YEAR($G15),MONTH($G15),1),$G$5:$G$404,"<="&EOMONTH($G15,0))>SUMIFS('利用者マスタ'!$B$4:$B$60,'利用者マスタ'!$A$4:$A$60,$B15),"⚠支給量超過",""))) | AA15: =IF(OR($G15="",$J15="",$Q15="キャンセル"),0,IF(IFERROR(INDEX('M_区分'!$B$4:$B$20,MATCH($C15,'M_区分'!$A$4:$A$20,0)),"○")="○",$J15-$G15+1,0)) | AB15: =IF($E15<>"",$E15,$AB14) | AC15: =IF(OR($G15="",$J15=""),"",IF(AND($G15<=EOMONTH('02_カレンダー'!$B$4,0),$J15>='02_カレンダー'!$B$4),$G15*10000+ROW(),"")) | AD15: =IF($H15="","",IF(ISNUMBER($H15),IF(AND($H15=INT($H15),$H15>=0,$H15<=24),TEXT(INT($H15),"00")&":00",TEXT($H15,"hh:mm")),$H15)) | AE15: =IF($K15="","",IF(ISNUMBER($K15),IF(AND($K15=INT($K15),$K15>=0,$K15<=24),TEXT(INT($K15),"00")&":00",TEXT($K15,"hh:mm")),$K15)) | AF15: =IF($G15="",0,$G15) | AG15: =IF($J15="",0,$J15)
A16: =IF($G16="","","SS-"&TEXT(ROW()-4,"0000")) | G16: =IF($F16="","",IF($F16>31,$F16,IF($AB16="","",DATE(YEAR($AB16),MONTH($AB16),$F16)))) | J16: =IF($I16="","",IF($I16>31,$I16,IF($G16="","",IF(DATE(YEAR($G16),MONTH($G16),$I16)>=$G16,DATE(YEAR($G16),MONTH($G16),$I16),DATE(YEAR($G16),MONTH($G16)+1,$I16))))) | O16: =IF(OR($G16="",$J16=""),"",$J16-$G16+1) | P16: =IF(OR($G16="",$J16=""),"",$J16-$G16) | Y16: =IF($G16="","",IF($D16="","⚠部屋が未選択",IF(COUNTIF('M_部屋'!$A$4:$A$20,$D16)=0,"⚠部屋が未登録",IF(OR($J16="",$Q16="キャンセル"),"",IF(SUMPRODUCT(($D$5:$D$404=$D16)*($G$5:$G$404<>"")*($J$5:$J$404<>"")*($Q$5:$Q$404<>"キャンセル")*($G$5:$G$404<$J16)*($J$5:$J$404>$G16))>1,"⚠重複",""))))) | Z16: =IF(OR($B16="",$G16=""),"",IF(SUMPRODUCT(('利用者マスタ'!$A$4:$A$60=$B16)*('利用者マスタ'!$B$4:$B$60<>""))=0,"",IF(SUMIFS($AA$5:$AA$404,$B$5:$B$404,$B16,$G$5:$G$404,">="&DATE(YEAR($G16),MONTH($G16),1),$G$5:$G$404,"<="&EOMONTH($G16,0))>SUMIFS('利用者マスタ'!$B$4:$B$60,'利用者マスタ'!$A$4:$A$60,$B16),"⚠支給量超過",""))) | AA16: =IF(OR($G16="",$J16="",$Q16="キャンセル"),0,IF(IFERROR(INDEX('M_区分'!$B$4:$B$20,MATCH($C16,'M_区分'!$A$4:$A$20,0)),"○")="○",$J16-$G16+1,0)) | AB16: =IF($E16<>"",$E16,$AB15) | AC16: =IF(OR($G16="",$J16=""),"",IF(AND($G16<=EOMONTH('02_カレンダー'!$B$4,0),$J16>='02_カレンダー'!$B$4),$G16*10000+ROW(),"")) | AD16: =IF($H16="","",IF(ISNUMBER($H16),IF(AND($H16=INT($H16),$H16>=0,$H16<=24),TEXT(INT($H16),"00")&":00",TEXT($H16,"hh:mm")),$H16)) | AE16: =IF($K16="","",IF(ISNUMBER($K16),IF(AND($K16=INT($K16),$K16>=0,$K16<=24),TEXT(INT($K16),"00")&":00",TEXT($K16,"hh:mm")),$K16)) | AF16: =IF($G16="",0,$G16) | AG16: =IF($J16="",0,$J16)
A17: =IF($G17="","","SS-"&TEXT(ROW()-4,"0000")) | G17: =IF($F17="","",IF($F17>31,$F17,IF($AB17="","",DATE(YEAR($AB17),MONTH($AB17),$F17)))) | J17: =IF($I17="","",IF($I17>31,$I17,IF($G17="","",IF(DATE(YEAR($G17),MONTH($G17),$I17)>=$G17,DATE(YEAR($G17),MONTH($G17),$I17),DATE(YEAR($G17),MONTH($G17)+1,$I17))))) | O17: =IF(OR($G17="",$J17=""),"",$J17-$G17+1) | P17: =IF(OR($G17="",$J17=""),"",$J17-$G17) | Y17: =IF($G17="","",IF($D17="","⚠部屋が未選択",IF(COUNTIF('M_部屋'!$A$4:$A$20,$D17)=0,"⚠部屋が未登録",IF(OR($J17="",$Q17="キャンセル"),"",IF(SUMPRODUCT(($D$5:$D$404=$D17)*($G$5:$G$404<>"")*($J$5:$J$404<>"")*($Q$5:$Q$404<>"キャンセル")*($G$5:$G$404<$J17)*($J$5:$J$404>$G17))>1,"⚠重複",""))))) | Z17: =IF(OR($B17="",$G17=""),"",IF(SUMPRODUCT(('利用者マスタ'!$A$4:$A$60=$B17)*('利用者マスタ'!$B$4:$B$60<>""))=0,"",IF(SUMIFS($AA$5:$AA$404,$B$5:$B$404,$B17,$G$5:$G$404,">="&DATE(YEAR($G17),MONTH($G17),1),$G$5:$G$404,"<="&EOMONTH($G17,0))>SUMIFS('利用者マスタ'!$B$4:$B$60,'利用者マスタ'!$A$4:$A$60,$B17),"⚠支給量超過",""))) | AA17: =IF(OR($G17="",$J17="",$Q17="キャンセル"),0,IF(IFERROR(INDEX('M_区分'!$B$4:$B$20,MATCH($C17,'M_区分'!$A$4:$A$20,0)),"○")="○",$J17-$G17+1,0)) | AB17: =IF($E17<>"",$E17,$AB16) | AC17: =IF(OR($G17="",$J17=""),"",IF(AND($G17<=EOMONTH('02_カレンダー'!$B$4,0),$J17>='02_カレンダー'!$B$4),$G17*10000+ROW(),"")) | AD17: =IF($H17="","",IF(ISNUMBER($H17),IF(AND($H17=INT($H17),$H17>=0,$H17<=24),TEXT(INT($H17),"00")&":00",TEXT($H17,"hh:mm")),$H17)) | AE17: =IF($K17="","",IF(ISNUMBER($K17),IF(AND($K17=INT($K17),$K17>=0,$K17<=24),TEXT(INT($K17),"00")&":00",TEXT($K17,"hh:mm")),$K17)) | AF17: =IF($G17="",0,$G17) | AG17: =IF($J17="",0,$J17)
A18: =IF($G18="","","SS-"&TEXT(ROW()-4,"0000")) | G18: =IF($F18="","",IF($F18>31,$F18,IF($AB18="","",DATE(YEAR($AB18),MONTH($AB18),$F18)))) | J18: =IF($I18="","",IF($I18>31,$I18,IF($G18="","",IF(DATE(YEAR($G18),MONTH($G18),$I18)>=$G18,DATE(YEAR($G18),MONTH($G18),$I18),DATE(YEAR($G18),MONTH($G18)+1,$I18))))) | O18: =IF(OR($G18="",$J18=""),"",$J18-$G18+1) | P18: =IF(OR($G18="",$J18=""),"",$J18-$G18) | Y18: =IF($G18="","",IF($D18="","⚠部屋が未選択",IF(COUNTIF('M_部屋'!$A$4:$A$20,$D18)=0,"⚠部屋が未登録",IF(OR($J18="",$Q18="キャンセル"),"",IF(SUMPRODUCT(($D$5:$D$404=$D18)*($G$5:$G$404<>"")*($J$5:$J$404<>"")*($Q$5:$Q$404<>"キャンセル")*($G$5:$G$404<$J18)*($J$5:$J$404>$G18))>1,"⚠重複",""))))) | Z18: =IF(OR($B18="",$G18=""),"",IF(SUMPRODUCT(('利用者マスタ'!$A$4:$A$60=$B18)*('利用者マスタ'!$B$4:$B$60<>""))=0,"",IF(SUMIFS($AA$5:$AA$404,$B$5:$B$404,$B18,$G$5:$G$404,">="&DATE(YEAR($G18),MONTH($G18),1),$G$5:$G$404,"<="&EOMONTH($G18,0))>SUMIFS('利用者マスタ'!$B$4:$B$60,'利用者マスタ'!$A$4:$A$60,$B18),"⚠支給量超過",""))) | AA18: =IF(OR($G18="",$J18="",$Q18="キャンセル"),0,IF(IFERROR(INDEX('M_区分'!$B$4:$B$20,MATCH($C18,'M_区分'!$A$4:$A$20,0)),"○")="○",$J18-$G18+1,0)) | AB18: =IF($E18<>"",$E18,$AB17) | AC18: =IF(OR($G18="",$J18=""),"",IF(AND($G18<=EOMONTH('02_カレンダー'!$B$4,0),$J18>='02_カレンダー'!$B$4),$G18*10000+ROW(),"")) | AD18: =IF($H18="","",IF(ISNUMBER($H18),IF(AND($H18=INT($H18),$H18>=0,$H18<=24),TEXT(INT($H18),"00")&":00",TEXT($H18,"hh:mm")),$H18)) | AE18: =IF($K18="","",IF(ISNUMBER($K18),IF(AND($K18=INT($K18),$K18>=0,$K18<=24),TEXT(INT($K18),"00")&":00",TEXT($K18,"hh:mm")),$K18)) | AF18: =IF($G18="",0,$G18) | AG18: =IF($J18="",0,$J18)
A19: =IF($G19="","","SS-"&TEXT(ROW()-4,"0000")) | G19: =IF($F19="","",IF($F19>31,$F19,IF($AB19="","",DATE(YEAR($AB19),MONTH($AB19),$F19)))) | J19: =IF($I19="","",IF($I19>31,$I19,IF($G19="","",IF(DATE(YEAR($G19),MONTH($G19),$I19)>=$G19,DATE(YEAR($G19),MONTH($G19),$I19),DATE(YEAR($G19),MONTH($G19)+1,$I19))))) | O19: =IF(OR($G19="",$J19=""),"",$J19-$G19+1) | P19: =IF(OR($G19="",$J19=""),"",$J19-$G19) | Y19: =IF($G19="","",IF($D19="","⚠部屋が未選択",IF(COUNTIF('M_部屋'!$A$4:$A$20,$D19)=0,"⚠部屋が未登録",IF(OR($J19="",$Q19="キャンセル"),"",IF(SUMPRODUCT(($D$5:$D$404=$D19)*($G$5:$G$404<>"")*($J$5:$J$404<>"")*($Q$5:$Q$404<>"キャンセル")*($G$5:$G$404<$J19)*($J$5:$J$404>$G19))>1,"⚠重複",""))))) | Z19: =IF(OR($B19="",$G19=""),"",IF(SUMPRODUCT(('利用者マスタ'!$A$4:$A$60=$B19)*('利用者マスタ'!$B$4:$B$60<>""))=0,"",IF(SUMIFS($AA$5:$AA$404,$B$5:$B$404,$B19,$G$5:$G$404,">="&DATE(YEAR($G19),MONTH($G19),1),$G$5:$G$404,"<="&EOMONTH($G19,0))>SUMIFS('利用者マスタ'!$B$4:$B$60,'利用者マスタ'!$A$4:$A$60,$B19),"⚠支給量超過",""))) | AA19: =IF(OR($G19="",$J19="",$Q19="キャンセル"),0,IF(IFERROR(INDEX('M_区分'!$B$4:$B$20,MATCH($C19,'M_区分'!$A$4:$A$20,0)),"○")="○",$J19-$G19+1,0)) | AB19: =IF($E19<>"",$E19,$AB18) | AC19: =IF(OR($G19="",$J19=""),"",IF(AND($G19<=EOMONTH('02_カレンダー'!$B$4,0),$J19>='02_カレンダー'!$B$4),$G19*10000+ROW(),"")) | AD19: =IF($H19="","",IF(ISNUMBER($H19),IF(AND($H19=INT($H19),$H19>=0,$H19<=24),TEXT(INT($H19),"00")&":00",TEXT($H19,"hh:mm")),$H19)) | AE19: =IF($K19="","",IF(ISNUMBER($K19),IF(AND($K19=INT($K19),$K19>=0,$K19<=24),TEXT(INT($K19),"00")&":00",TEXT($K19,"hh:mm")),$K19)) | AF19: =IF($G19="",0,$G19) | AG19: =IF($J19="",0,$J19)
A20: =IF($G20="","","SS-"&TEXT(ROW()-4,"0000")) | G20: =IF($F20="","",IF($F20>31,$F20,IF($AB20="","",DATE(YEAR($AB20),MONTH($AB20),$F20)))) | J20: =IF($I20="","",IF($I20>31,$I20,IF($G20="","",IF(DATE(YEAR($G20),MONTH($G20),$I20)>=$G20,DATE(YEAR($G20),MONTH($G20),$I20),DATE(YEAR($G20),MONTH($G20)+1,$I20))))) | O20: =IF(OR($G20="",$J20=""),"",$J20-$G20+1) | P20: =IF(OR($G20="",$J20=""),"",$J20-$G20) | Y20: =IF($G20="","",IF($D20="","⚠部屋が未選択",IF(COUNTIF('M_部屋'!$A$4:$A$20,$D20)=0,"⚠部屋が未登録",IF(OR($J20="",$Q20="キャンセル"),"",IF(SUMPRODUCT(($D$5:$D$404=$D20)*($G$5:$G$404<>"")*($J$5:$J$404<>"")*($Q$5:$Q$404<>"キャンセル")*($G$5:$G$404<$J20)*($J$5:$J$404>$G20))>1,"⚠重複",""))))) | Z20: =IF(OR($B20="",$G20=""),"",IF(SUMPRODUCT(('利用者マスタ'!$A$4:$A$60=$B20)*('利用者マスタ'!$B$4:$B$60<>""))=0,"",IF(SUMIFS($AA$5:$AA$404,$B$5:$B$404,$B20,$G$5:$G$404,">="&DATE(YEAR($G20),MONTH($G20),1),$G$5:$G$404,"<="&EOMONTH($G20,0))>SUMIFS('利用者マスタ'!$B$4:$B$60,'利用者マスタ'!$A$4:$A$60,$B20),"⚠支給量超過",""))) | AA20: =IF(OR($G20="",$J20="",$Q20="キャンセル"),0,IF(IFERROR(INDEX('M_区分'!$B$4:$B$20,MATCH($C20,'M_区分'!$A$4:$A$20,0)),"○")="○",$J20-$G20+1,0)) | AB20: =IF($E20<>"",$E20,$AB19) | AC20: =IF(OR($G20="",$J20=""),"",IF(AND($G20<=EOMONTH('02_カレンダー'!$B$4,0),$J20>='02_カレンダー'!$B$4),$G20*10000+ROW(),"")) | AD20: =IF($H20="","",IF(ISNUMBER($H20),IF(AND($H20=INT($H20),$H20>=0,$H20<=24),TEXT(INT($H20),"00")&":00",TEXT($H20,"hh:mm")),$H20)) | AE20: =IF($K20="","",IF(ISNUMBER($K20),IF(AND($K20=INT($K20),$K20>=0,$K20<=24),TEXT(INT($K20),"00")&":00",TEXT($K20,"hh:mm")),$K20)) | AF20: =IF($G20="",0,$G20) | AG20: =IF($J20="",0,$J20)
A21: =IF($G21="","","SS-"&TEXT(ROW()-4,"0000")) | G21: =IF($F21="","",IF($F21>31,$F21,IF($AB21="","",DATE(YEAR($AB21),MONTH($AB21),$F21)))) | J21: =IF($I21="","",IF($I21>31,$I21,IF($G21="","",IF(DATE(YEAR($G21),MONTH($G21),$I21)>=$G21,DATE(YEAR($G21),MONTH($G21),$I21),DATE(YEAR($G21),MONTH($G21)+1,$I21))))) | O21: =IF(OR($G21="",$J21=""),"",$J21-$G21+1) | P21: =IF(OR($G21="",$J21=""),"",$J21-$G21) | Y21: =IF($G21="","",IF($D21="","⚠部屋が未選択",IF(COUNTIF('M_部屋'!$A$4:$A$20,$D21)=0,"⚠部屋が未登録",IF(OR($J21="",$Q21="キャンセル"),"",IF(SUMPRODUCT(($D$5:$D$404=$D21)*($G$5:$G$404<>"")*($J$5:$J$404<>"")*($Q$5:$Q$404<>"キャンセル")*($G$5:$G$404<$J21)*($J$5:$J$404>$G21))>1,"⚠重複",""))))) | Z21: =IF(OR($B21="",$G21=""),"",IF(SUMPRODUCT(('利用者マスタ'!$A$4:$A$60=$B21)*('利用者マスタ'!$B$4:$B$60<>""))=0,"",IF(SUMIFS($AA$5:$AA$404,$B$5:$B$404,$B21,$G$5:$G$404,">="&DATE(YEAR($G21),MONTH($G21),1),$G$5:$G$404,"<="&EOMONTH($G21,0))>SUMIFS('利用者マスタ'!$B$4:$B$60,'利用者マスタ'!$A$4:$A$60,$B21),"⚠支給量超過",""))) | AA21: =IF(OR($G21="",$J21="",$Q21="キャンセル"),0,IF(IFERROR(INDEX('M_区分'!$B$4:$B$20,MATCH($C21,'M_区分'!$A$4:$A$20,0)),"○")="○",$J21-$G21+1,0)) | AB21: =IF($E21<>"",$E21,$AB20) | AC21: =IF(OR($G21="",$J21=""),"",IF(AND($G21<=EOMONTH('02_カレンダー'!$B$4,0),$J21>='02_カレンダー'!$B$4),$G21*10000+ROW(),"")) | AD21: =IF($H21="","",IF(ISNUMBER($H21),IF(AND($H21=INT($H21),$H21>=0,$H21<=24),TEXT(INT($H21),"00")&":00",TEXT($H21,"hh:mm")),$H21)) | AE21: =IF($K21="","",IF(ISNUMBER($K21),IF(AND($K21=INT($K21),$K21>=0,$K21<=24),TEXT(INT($K21),"00")&":00",TEXT($K21,"hh:mm")),$K21)) | AF21: =IF($G21="",0,$G21) | AG21: =IF($J21="",0,$J21)
A22: =IF($G22="","","SS-"&TEXT(ROW()-4,"0000")) | G22: =IF($F22="","",IF($F22>31,$F22,IF($AB22="","",DATE(YEAR($AB22),MONTH($AB22),$F22)))) | J22: =IF($I22="","",IF($I22>31,$I22,IF($G22="","",IF(DATE(YEAR($G22),MONTH($G22),$I22)>=$G22,DATE(YEAR($G22),MONTH($G22),$I22),DATE(YEAR($G22),MONTH($G22)+1,$I22))))) | O22: =IF(OR($G22="",$J22=""),"",$J22-$G22+1) | P22: =IF(OR($G22="",$J22=""),"",$J22-$G22) | Y22: =IF($G22="","",IF($D22="","⚠部屋が未選択",IF(COUNTIF('M_部屋'!$A$4:$A$20,$D22)=0,"⚠部屋が未登録",IF(OR($J22="",$Q22="キャンセル"),"",IF(SUMPRODUCT(($D$5:$D$404=$D22)*($G$5:$G$404<>"")*($J$5:$J$404<>"")*($Q$5:$Q$404<>"キャンセル")*($G$5:$G$404<$J22)*($J$5:$J$404>$G22))>1,"⚠重複",""))))) | Z22: =IF(OR($B22="",$G22=""),"",IF(SUMPRODUCT(('利用者マスタ'!$A$4:$A$60=$B22)*('利用者マスタ'!$B$4:$B$60<>""))=0,"",IF(SUMIFS($AA$5:$AA$404,$B$5:$B$404,$B22,$G$5:$G$404,">="&DATE(YEAR($G22),MONTH($G22),1),$G$5:$G$404,"<="&EOMONTH($G22,0))>SUMIFS('利用者マスタ'!$B$4:$B$60,'利用者マスタ'!$A$4:$A$60,$B22),"⚠支給量超過",""))) | AA22: =IF(OR($G22="",$J22="",$Q22="キャンセル"),0,IF(IFERROR(INDEX('M_区分'!$B$4:$B$20,MATCH($C22,'M_区分'!$A$4:$A$20,0)),"○")="○",$J22-$G22+1,0)) | AB22: =IF($E22<>"",$E22,$AB21) | AC22: =IF(OR($G22="",$J22=""),"",IF(AND($G22<=EOMONTH('02_カレンダー'!$B$4,0),$J22>='02_カレンダー'!$B$4),$G22*10000+ROW(),"")) | AD22: =IF($H22="","",IF(ISNUMBER($H22),IF(AND($H22=INT($H22),$H22>=0,$H22<=24),TEXT(INT($H22),"00")&":00",TEXT($H22,"hh:mm")),$H22)) | AE22: =IF($K22="","",IF(ISNUMBER($K22),IF(AND($K22=INT($K22),$K22>=0,$K22<=24),TEXT(INT($K22),"00")&":00",TEXT($K22,"hh:mm")),$K22)) | AF22: =IF($G22="",0,$G22) | AG22: =IF($J22="",0,$J22)
A23: =IF($G23="","","SS-"&TEXT(ROW()-4,"0000")) | G23: =IF($F23="","",IF($F23>31,$F23,IF($AB23="","",DATE(YEAR($AB23),MONTH($AB23),$F23)))) | J23: =IF($I23="","",IF($I23>31,$I23,IF($G23="","",IF(DATE(YEAR($G23),MONTH($G23),$I23)>=$G23,DATE(YEAR($G23),MONTH($G23),$I23),DATE(YEAR($G23),MONTH($G23)+1,$I23))))) | O23: =IF(OR($G23="",$J23=""),"",$J23-$G23+1) | P23: =IF(OR($G23="",$J23=""),"",$J23-$G23) | Y23: =IF($G23="","",IF($D23="","⚠部屋が未選択",IF(COUNTIF('M_部屋'!$A$4:$A$20,$D23)=0,"⚠部屋が未登録",IF(OR($J23="",$Q23="キャンセル"),"",IF(SUMPRODUCT(($D$5:$D$404=$D23)*($G$5:$G$404<>"")*($J$5:$J$404<>"")*($Q$5:$Q$404<>"キャンセル")*($G$5:$G$404<$J23)*($J$5:$J$404>$G23))>1,"⚠重複",""))))) | Z23: =IF(OR($B23="",$G23=""),"",IF(SUMPRODUCT(('利用者マスタ'!$A$4:$A$60=$B23)*('利用者マスタ'!$B$4:$B$60<>""))=0,"",IF(SUMIFS($AA$5:$AA$404,$B$5:$B$404,$B23,$G$5:$G$404,">="&DATE(YEAR($G23),MONTH($G23),1),$G$5:$G$404,"<="&EOMONTH($G23,0))>SUMIFS('利用者マスタ'!$B$4:$B$60,'利用者マスタ'!$A$4:$A$60,$B23),"⚠支給量超過",""))) | AA23: =IF(OR($G23="",$J23="",$Q23="キャンセル"),0,IF(IFERROR(INDEX('M_区分'!$B$4:$B$20,MATCH($C23,'M_区分'!$A$4:$A$20,0)),"○")="○",$J23-$G23+1,0)) | AB23: =IF($E23<>"",$E23,$AB22) | AC23: =IF(OR($G23="",$J23=""),"",IF(AND($G23<=EOMONTH('02_カレンダー'!$B$4,0),$J23>='02_カレンダー'!$B$4),$G23*10000+ROW(),"")) | AD23: =IF($H23="","",IF(ISNUMBER($H23),IF(AND($H23=INT($H23),$H23>=0,$H23<=24),TEXT(INT($H23),"00")&":00",TEXT($H23,"hh:mm")),$H23)) | AE23: =IF($K23="","",IF(ISNUMBER($K23),IF(AND($K23=INT($K23),$K23>=0,$K23<=24),TEXT(INT($K23),"00")&":00",TEXT($K23,"hh:mm")),$K23)) | AF23: =IF($G23="",0,$G23) | AG23: =IF($J23="",0,$J23)
A24: =IF($G24="","","SS-"&TEXT(ROW()-4,"0000")) | G24: =IF($F24="","",IF($F24>31,$F24,IF($AB24="","",DATE(YEAR($AB24),MONTH($AB24),$F24)))) | J24: =IF($I24="","",IF($I24>31,$I24,IF($G24="","",IF(DATE(YEAR($G24),MONTH($G24),$I24)>=$G24,DATE(YEAR($G24),MONTH($G24),$I24),DATE(YEAR($G24),MONTH($G24)+1,$I24))))) | O24: =IF(OR($G24="",$J24=""),"",$J24-$G24+1) | P24: =IF(OR($G24="",$J24=""),"",$J24-$G24) | Y24: =IF($G24="","",IF($D24="","⚠部屋が未選択",IF(COUNTIF('M_部屋'!$A$4:$A$20,$D24)=0,"⚠部屋が未登録",IF(OR($J24="",$Q24="キャンセル"),"",IF(SUMPRODUCT(($D$5:$D$404=$D24)*($G$5:$G$404<>"")*($J$5:$J$404<>"")*($Q$5:$Q$404<>"キャンセル")*($G$5:$G$404<$J24)*($J$5:$J$404>$G24))>1,"⚠重複",""))))) | Z24: =IF(OR($B24="",$G24=""),"",IF(SUMPRODUCT(('利用者マスタ'!$A$4:$A$60=$B24)*('利用者マスタ'!$B$4:$B$60<>""))=0,"",IF(SUMIFS($AA$5:$AA$404,$B$5:$B$404,$B24,$G$5:$G$404,">="&DATE(YEAR($G24),MONTH($G24),1),$G$5:$G$404,"<="&EOMONTH($G24,0))>SUMIFS('利用者マスタ'!$B$4:$B$60,'利用者マスタ'!$A$4:$A$60,$B24),"⚠支給量超過",""))) | AA24: =IF(OR($G24="",$J24="",$Q24="キャンセル"),0,IF(IFERROR(INDEX('M_区分'!$B$4:$B$20,MATCH($C24,'M_区分'!$A$4:$A$20,0)),"○")="○",$J24-$G24+1,0)) | AB24: =IF($E24<>"",$E24,$AB23) | AC24: =IF(OR($G24="",$J24=""),"",IF(AND($G24<=EOMONTH('02_カレンダー'!$B$4,0),$J24>='02_カレンダー'!$B$4),$G24*10000+ROW(),"")) | AD24: =IF($H24="","",IF(ISNUMBER($H24),IF(AND($H24=INT($H24),$H24>=0,$H24<=24),TEXT(INT($H24),"00")&":00",TEXT($H24,"hh:mm")),$H24)) | AE24: =IF($K24="","",IF(ISNUMBER($K24),IF(AND($K24=INT($K24),$K24>=0,$K24<=24),TEXT(INT($K24),"00")&":00",TEXT($K24,"hh:mm")),$K24)) | AF24: =IF($G24="",0,$G24) | AG24: =IF($J24="",0,$J24)
A25: =IF($G25="","","SS-"&TEXT(ROW()-4,"0000")) | G25: =IF($F25="","",IF($F25>31,$F25,IF($AB25="","",DATE(YEAR($AB25),MONTH($AB25),$F25)))) | J25: =IF($I25="","",IF($I25>31,$I25,IF($G25="","",IF(DATE(YEAR($G25),MONTH($G25),$I25)>=$G25,DATE(YEAR($G25),MONTH($G25),$I25),DATE(YEAR($G25),MONTH($G25)+1,$I25))))) | O25: =IF(OR($G25="",$J25=""),"",$J25-$G25+1) | P25: =IF(OR($G25="",$J25=""),"",$J25-$G25) | Y25: =IF($G25="","",IF($D25="","⚠部屋が未選択",IF(COUNTIF('M_部屋'!$A$4:$A$20,$D25)=0,"⚠部屋が未登録",IF(OR($J25="",$Q25="キャンセル"),"",IF(SUMPRODUCT(($D$5:$D$404=$D25)*($G$5:$G$404<>"")*($J$5:$J$404<>"")*($Q$5:$Q$404<>"キャンセル")*($G$5:$G$404<$J25)*($J$5:$J$404>$G25))>1,"⚠重複",""))))) | Z25: =IF(OR($B25="",$G25=""),"",IF(SUMPRODUCT(('利用者マスタ'!$A$4:$A$60=$B25)*('利用者マスタ'!$B$4:$B$60<>""))=0,"",IF(SUMIFS($AA$5:$AA$404,$B$5:$B$404,$B25,$G$5:$G$404,">="&DATE(YEAR($G25),MONTH($G25),1),$G$5:$G$404,"<="&EOMONTH($G25,0))>SUMIFS('利用者マスタ'!$B$4:$B$60,'利用者マスタ'!$A$4:$A$60,$B25),"⚠支給量超過",""))) | AA25: =IF(OR($G25="",$J25="",$Q25="キャンセル"),0,IF(IFERROR(INDEX('M_区分'!$B$4:$B$20,MATCH($C25,'M_区分'!$A$4:$A$20,0)),"○")="○",$J25-$G25+1,0)) | AB25: =IF($E25<>"",$E25,$AB24) | AC25: =IF(OR($G25="",$J25=""),"",IF(AND($G25<=EOMONTH('02_カレンダー'!$B$4,0),$J25>='02_カレンダー'!$B$4),$G25*10000+ROW(),"")) | AD25: =IF($H25="","",IF(ISNUMBER($H25),IF(AND($H25=INT($H25),$H25>=0,$H25<=24),TEXT(INT($H25),"00")&":00",TEXT($H25,"hh:mm")),$H25)) | AE25: =IF($K25="","",IF(ISNUMBER($K25),IF(AND($K25=INT($K25),$K25>=0,$K25<=24),TEXT(INT($K25),"00")&":00",TEXT($K25,"hh:mm")),$K25)) | AF25: =IF($G25="",0,$G25) | AG25: =IF($J25="",0,$J25)
... A404: =IF($G404="","","SS-"&TEXT(ROW()-4,"0000")) | G404: =IF($F404="","",IF($F404>31,$F404,IF($AB404="","",DATE(YEAR($AB404),MONTH($AB404),$F404)))) | J404: =IF($I404="","",IF($I404>31,$I404,IF($G404="","",IF(DATE(YEAR($G404),MONTH($G404),$I404)>=$G404,DATE(YEAR($G404),MONTH($G404),$I404),DATE(YEAR($G404),MONTH($G404)+1,$I404))))) | O404: =IF(OR($G404="",$J404=""),"",$J404-$G404+1) | P404: =IF(OR($G404="",$J404=""),"",$J404-$G404) | Y404: =IF($G404="","",IF($D404="","⚠部屋が未選択",IF(COUNTIF('M_部屋'!$A$4:$A$20,$D404)=0,"⚠部屋が未登録",IF(OR($J404="",$Q404="キャンセル"),"",IF(SUMPRODUCT(($D$5:$D$404=$D404)*($G$5:$G$404<>"")*($J$5:$J$404<>"")*($Q$5:$Q$404<>"キャンセル")*($G$5:$G$404<$J404)*($J$5:$J$404>$G404))>1,"⚠重複",""))))) | Z404: =IF(OR($B404="",$G404=""),"",IF(SUMPRODUCT(('利用者マスタ'!$A$4:$A$60=$B404)*('利用者マスタ'!$B$4:$B$60<>""))=0,"",IF(SUMIFS($AA$5:$AA$404,$B$5:$B$404,$B404,$G$5:$G$404,">="&DATE(YEAR($G404),MONTH($G404),1),$G$5:$G$404,"<="&EOMONTH($G404,0))>SUMIFS('利用者マスタ'!$B$4:$B$60,'利用者マスタ'!$A$4:$A$60,$B404),"⚠支給量超過",""))) | AA404: =IF(OR($G404="",$J404="",$Q404="キャンセル"),0,IF(IFERROR(INDEX('M_区分'!$B$4:$B$20,MATCH($C404,'M_区分'!$A$4:$A$20,0)),"○")="○",$J404-$G404+1,0)) | AB404: =IF($E404<>"",$E404,$AB403) | AC404: =IF(OR($G404="",$J404=""),"",IF(AND($G404<=EOMONTH('02_カレンダー'!$B$4,0),$J404>='02_カレンダー'!$B$4),$G404*10000+ROW(),"")) | AD404: =IF($H404="","",IF(ISNUMBER($H404),IF(AND($H404=INT($H404),$H404>=0,$H404<=24),TEXT(INT($H404),"00")&":00",TEXT($H404,"hh:mm")),$H404)) | AE404: =IF($K404="","",IF(ISNUMBER($K404),IF(AND($K404=INT($K404),$K404>=0,$K404<=24),TEXT(INT($K404),"00")&":00",TEXT($K404,"hh:mm")),$K404)) | AF404: =IF($G404="",0,$G404) | AG404: =IF($J404="",0,$J404)

Sheet 02_カレンダー
A1: カレンダー
A2: ★対象月を変えると、03_帯表・04_月間表・06_食数表・09_FAX空き表 も同じ月になります。
A3: 対象月 | B3: 46235 | C3: ="その月の日付ならどれでも可。 【今日は "&YEAR(TODAY())&"年"&MONTH(TODAY())&"月"&DAY(TODAY())&"日】 "&IF(TEXT($B$3,"yyyymm")=TEXT(TODAY(),"yyyymm"),"（今月を表示しています）","← 今月に切り替えるときはここを直します")
A4: 月初 | B4: =DATE(YEAR($B$3),MONTH($B$3),1) | C4: 自動
A5: 時刻を表示 | B5: ○ | C5: ○で入室・退室時刻を表示。狭く感じるときは空欄に
A6: 食事を表示 | B6: ○ | C6: ○で各週の下に朝・昼・夕の食数を表示。個別の調整はこのシートの下部で
A7: 確認 | B7: =IF(SUMPRODUCT(('01_予約入力'!$D$5:$D$404="")*('01_予約入力'!$G$5:$G$404<>""))=0,"✓ 部屋の指定もれはありません","⚠ 部屋が未選択の予約が "&SUMPRODUCT(('01_予約入力'!$D$5:$D$404="")*('01_予約入力'!$G$5:$G$404<>""))&" 件あります。部屋の行には出ませんが「空き」の判定には数えています。01_予約入力 のV列（赤）をご確認ください。")
A8: 記号 | B8: 日 | C8: 月 | D8: 火 | E8: 水 | F8: 木 | G8: 金 | H8: 土
A9: 第1週 | B9: =IF(MONTH($B$4-WEEKDAY($B$4)+1+0)<>MONTH($B$4),"",$B$4-WEEKDAY($B$4)+1+0) | C9: =IF(MONTH($B$4-WEEKDAY($B$4)+1+1)<>MONTH($B$4),"",$B$4-WEEKDAY($B$4)+1+1) | D9: =IF(MONTH($B$4-WEEKDAY($B$4)+1+2)<>MONTH($B$4),"",$B$4-WEEKDAY($B$4)+1+2) | E9: =IF(MONTH($B$4-WEEKDAY($B$4)+1+3)<>MONTH($B$4),"",$B$4-WEEKDAY($B$4)+1+3) | F9: =IF(MONTH($B$4-WEEKDAY($B$4)+1+4)<>MONTH($B$4),"",$B$4-WEEKDAY($B$4)+1+4) | G9: =IF(MONTH($B$4-WEEKDAY($B$4)+1+5)<>MONTH($B$4),"",$B$4-WEEKDAY($B$4)+1+5) | H9: =IF(MONTH($B$4-WEEKDAY($B$4)+1+6)<>MONTH($B$4),"",$B$4-WEEKDAY($B$4)+1+6)
A10: =IF(COUNTA('M_部屋'!$A$4:$A$20)>=1,INDEX('M_部屋'!$A$4:$A$20,1),"") | B10: =IF(B9="","",IFERROR(INDEX('04_月間表'!C$7:C$37,MATCH(B9,'04_月間表'!$A$7:$A$37,0)),"")) | C10: =IF(C9="","",IFERROR(INDEX('04_月間表'!C$7:C$37,MATCH(C9,'04_月間表'!$A$7:$A$37,0)),"")) | D10: =IF(D9="","",IFERROR(INDEX('04_月間表'!C$7:C$37,MATCH(D9,'04_月間表'!$A$7:$A$37,0)),"")) | E10: =IF(E9="","",IFERROR(INDEX('04_月間表'!C$7:C$37,MATCH(E9,'04_月間表'!$A$7:$A$37,0)),"")) | F10: =IF(F9="","",IFERROR(INDEX('04_月間表'!C$7:C$37,MATCH(F9,'04_月間表'!$A$7:$A$37,0)),"")) | G10: =IF(G9="","",IFERROR(INDEX('04_月間表'!C$7:C$37,MATCH(G9,'04_月間表'!$A$7:$A$37,0)),"")) | H10: =IF(H9="","",IFERROR(INDEX('04_月間表'!C$7:C$37,MATCH(H9,'04_月間表'!$A$7:$A$37,0)),"")) | J10: =IF(B9="","",IFERROR(INDEX('04_月間表'!X$7:X$37,MATCH(B9,'04_月間表'!$A$7:$A$37,0)),"")) | K10: =IF(C9="","",IFERROR(INDEX('04_月間表'!X$7:X$37,MATCH(C9,'04_月間表'!$A$7:$A$37,0)),"")) | L10: =IF(D9="","",IFERROR(INDEX('04_月間表'!X$7:X$37,MATCH(D9,'04_月間表'!$A$7:$A$37,0)),"")) | M10: =IF(E9="","",IFERROR(INDEX('04_月間表'!X$7:X$37,MATCH(E9,'04_月間表'!$A$7:$A$37,0)),"")) | N10: =IF(F9="","",IFERROR(INDEX('04_月間表'!X$7:X$37,MATCH(F9,'04_月間表'!$A$7:$A$37,0)),"")) | O10: =IF(G9="","",IFERROR(INDEX('04_月間表'!X$7:X$37,MATCH(G9,'04_月間表'!$A$7:$A$37,0)),"")) | P10: =IF(H9="","",IFERROR(INDEX('04_月間表'!X$7:X$37,MATCH(H9,'04_月間表'!$A$7:$A$37,0)),""))
A11: =IF(COUNTA('M_部屋'!$A$4:$A$20)>=2,INDEX('M_部屋'!$A$4:$A$20,2),"") | B11: =IF(B9="","",IFERROR(INDEX('04_月間表'!D$7:D$37,MATCH(B9,'04_月間表'!$A$7:$A$37,0)),"")) | C11: =IF(C9="","",IFERROR(INDEX('04_月間表'!D$7:D$37,MATCH(C9,'04_月間表'!$A$7:$A$37,0)),"")) | D11: =IF(D9="","",IFERROR(INDEX('04_月間表'!D$7:D$37,MATCH(D9,'04_月間表'!$A$7:$A$37,0)),"")) | E11: =IF(E9="","",IFERROR(INDEX('04_月間表'!D$7:D$37,MATCH(E9,'04_月間表'!$A$7:$A$37,0)),"")) | F11: =IF(F9="","",IFERROR(INDEX('04_月間表'!D$7:D$37,MATCH(F9,'04_月間表'!$A$7:$A$37,0)),"")) | G11: =IF(G9="","",IFERROR(INDEX('04_月間表'!D$7:D$37,MATCH(G9,'04_月間表'!$A$7:$A$37,0)),"")) | H11: =IF(H9="","",IFERROR(INDEX('04_月間表'!D$7:D$37,MATCH(H9,'04_月間表'!$A$7:$A$37,0)),"")) | J11: =IF(B9="","",IFERROR(INDEX('04_月間表'!Y$7:Y$37,MATCH(B9,'04_月間表'!$A$7:$A$37,0)),"")) | K11: =IF(C9="","",IFERROR(INDEX('04_月間表'!Y$7:Y$37,MATCH(C9,'04_月間表'!$A$7:$A$37,0)),"")) | L11: =IF(D9="","",IFERROR(INDEX('04_月間表'!Y$7:Y$37,MATCH(D9,'04_月間表'!$A$7:$A$37,0)),"")) | M11: =IF(E9="","",IFERROR(INDEX('04_月間表'!Y$7:Y$37,MATCH(E9,'04_月間表'!$A$7:$A$37,0)),"")) | N11: =IF(F9="","",IFERROR(INDEX('04_月間表'!Y$7:Y$37,MATCH(F9,'04_月間表'!$A$7:$A$37,0)),"")) | O11: =IF(G9="","",IFERROR(INDEX('04_月間表'!Y$7:Y$37,MATCH(G9,'04_月間表'!$A$7:$A$37,0)),"")) | P11: =IF(H9="","",IFERROR(INDEX('04_月間表'!Y$7:Y$37,MATCH(H9,'04_月間表'!$A$7:$A$37,0)),""))
A12: =IF(COUNTA('M_部屋'!$A$4:$A$20)>=3,INDEX('M_部屋'!$A$4:$A$20,3),"") | B12: =IF(B9="","",IFERROR(INDEX('04_月間表'!E$7:E$37,MATCH(B9,'04_月間表'!$A$7:$A$37,0)),"")) | C12: =IF(C9="","",IFERROR(INDEX('04_月間表'!E$7:E$37,MATCH(C9,'04_月間表'!$A$7:$A$37,0)),"")) | D12: =IF(D9="","",IFERROR(INDEX('04_月間表'!E$7:E$37,MATCH(D9,'04_月間表'!$A$7:$A$37,0)),"")) | E12: =IF(E9="","",IFERROR(INDEX('04_月間表'!E$7:E$37,MATCH(E9,'04_月間表'!$A$7:$A$37,0)),"")) | F12: =IF(F9="","",IFERROR(INDEX('04_月間表'!E$7:E$37,MATCH(F9,'04_月間表'!$A$7:$A$37,0)),"")) | G12: =IF(G9="","",IFERROR(INDEX('04_月間表'!E$7:E$37,MATCH(G9,'04_月間表'!$A$7:$A$37,0)),"")) | H12: =IF(H9="","",IFERROR(INDEX('04_月間表'!E$7:E$37,MATCH(H9,'04_月間表'!$A$7:$A$37,0)),"")) | J12: =IF(B9="","",IFERROR(INDEX('04_月間表'!Z$7:Z$37,MATCH(B9,'04_月間表'!$A$7:$A$37,0)),"")) | K12: =IF(C9="","",IFERROR(INDEX('04_月間表'!Z$7:Z$37,MATCH(C9,'04_月間表'!$A$7:$A$37,0)),"")) | L12: =IF(D9="","",IFERROR(INDEX('04_月間表'!Z$7:Z$37,MATCH(D9,'04_月間表'!$A$7:$A$37,0)),"")) | M12: =IF(E9="","",IFERROR(INDEX('04_月間表'!Z$7:Z$37,MATCH(E9,'04_月間表'!$A$7:$A$37,0)),"")) | N12: =IF(F9="","",IFERROR(INDEX('04_月間表'!Z$7:Z$37,MATCH(F9,'04_月間表'!$A$7:$A$37,0)),"")) | O12: =IF(G9="","",IFERROR(INDEX('04_月間表'!Z$7:Z$37,MATCH(G9,'04_月間表'!$A$7:$A$37,0)),"")) | P12: =IF(H9="","",IFERROR(INDEX('04_月間表'!Z$7:Z$37,MATCH(H9,'04_月間表'!$A$7:$A$37,0)),""))
A13: =IF(COUNTA('M_部屋'!$A$4:$A$20)>=4,INDEX('M_部屋'!$A$4:$A$20,4),"") | B13: =IF(B9="","",IFERROR(INDEX('04_月間表'!F$7:F$37,MATCH(B9,'04_月間表'!$A$7:$A$37,0)),"")) | C13: =IF(C9="","",IFERROR(INDEX('04_月間表'!F$7:F$37,MATCH(C9,'04_月間表'!$A$7:$A$37,0)),"")) | D13: =IF(D9="","",IFERROR(INDEX('04_月間表'!F$7:F$37,MATCH(D9,'04_月間表'!$A$7:$A$37,0)),"")) | E13: =IF(E9="","",IFERROR(INDEX('04_月間表'!F$7:F$37,MATCH(E9,'04_月間表'!$A$7:$A$37,0)),"")) | F13: =IF(F9="","",IFERROR(INDEX('04_月間表'!F$7:F$37,MATCH(F9,'04_月間表'!$A$7:$A$37,0)),"")) | G13: =IF(G9="","",IFERROR(INDEX('04_月間表'!F$7:F$37,MATCH(G9,'04_月間表'!$A$7:$A$37,0)),"")) | H13: =IF(H9="","",IFERROR(INDEX('04_月間表'!F$7:F$37,MATCH(H9,'04_月間表'!$A$7:$A$37,0)),"")) | J13: =IF(B9="","",IFERROR(INDEX('04_月間表'!AA$7:AA$37,MATCH(B9,'04_月間表'!$A$7:$A$37,0)),"")) | K13: =IF(C9="","",IFERROR(INDEX('04_月間表'!AA$7:AA$37,MATCH(C9,'04_月間表'!$A$7:$A$37,0)),"")) | L13: =IF(D9="","",IFERROR(INDEX('04_月間表'!AA$7:AA$37,MATCH(D9,'04_月間表'!$A$7:$A$37,0)),"")) | M13: =IF(E9="","",IFERROR(INDEX('04_月間表'!AA$7:AA$37,MATCH(E9,'04_月間表'!$A$7:$A$37,0)),"")) | N13: =IF(F9="","",IFERROR(INDEX('04_月間表'!AA$7:AA$37,MATCH(F9,'04_月間表'!$A$7:$A$37,0)),"")) | O13: =IF(G9="","",IFERROR(INDEX('04_月間表'!AA$7:AA$37,MATCH(G9,'04_月間表'!$A$7:$A$37,0)),"")) | P13: =IF(H9="","",IFERROR(INDEX('04_月間表'!AA$7:AA$37,MATCH(H9,'04_月間表'!$A$7:$A$37,0)),""))
A14: 空き | B14: =IF(B9="","",IFERROR(INDEX('04_月間表'!$J$7:$J$37,MATCH(B9,'04_月間表'!$A$7:$A$37,0)),"")) | C14: =IF(C9="","",IFERROR(INDEX('04_月間表'!$J$7:$J$37,MATCH(C9,'04_月間表'!$A$7:$A$37,0)),"")) | D14: =IF(D9="","",IFERROR(INDEX('04_月間表'!$J$7:$J$37,MATCH(D9,'04_月間表'!$A$7:$A$37,0)),"")) | E14: =IF(E9="","",IFERROR(INDEX('04_月間表'!$J$7:$J$37,MATCH(E9,'04_月間表'!$A$7:$A$37,0)),"")) | F14: =IF(F9="","",IFERROR(INDEX('04_月間表'!$J$7:$J$37,MATCH(F9,'04_月間表'!$A$7:$A$37,0)),"")) | G14: =IF(G9="","",IFERROR(INDEX('04_月間表'!$J$7:$J$37,MATCH(G9,'04_月間表'!$A$7:$A$37,0)),"")) | H14: =IF(H9="","",IFERROR(INDEX('04_月間表'!$J$7:$J$37,MATCH(H9,'04_月間表'!$A$7:$A$37,0)),""))
A15: 食事 | B15: =IF(OR(B9="",$B$6<>"○"),"",IFERROR(INDEX('04_月間表'!$AI$7:$AI$37,MATCH(B9,'04_月間表'!$A$7:$A$37,0)),"")) | C15: =IF(OR(C9="",$B$6<>"○"),"",IFERROR(INDEX('04_月間表'!$AI$7:$AI$37,MATCH(C9,'04_月間表'!$A$7:$A$37,0)),"")) | D15: =IF(OR(D9="",$B$6<>"○"),"",IFERROR(INDEX('04_月間表'!$AI$7:$AI$37,MATCH(D9,'04_月間表'!$A$7:$A$37,0)),"")) | E15: =IF(OR(E9="",$B$6<>"○"),"",IFERROR(INDEX('04_月間表'!$AI$7:$AI$37,MATCH(E9,'04_月間表'!$A$7:$A$37,0)),"")) | F15: =IF(OR(F9="",$B$6<>"○"),"",IFERROR(INDEX('04_月間表'!$AI$7:$AI$37,MATCH(F9,'04_月間表'!$A$7:$A$37,0)),"")) | G15: =IF(OR(G9="",$B$6<>"○"),"",IFERROR(INDEX('04_月間表'!$AI$7:$AI$37,MATCH(G9,'04_月間表'!$A$7:$A$37,0)),"")) | H15: =IF(OR(H9="",$B$6<>"○"),"",IFERROR(INDEX('04_月間表'!$AI$7:$AI$37,MATCH(H9,'04_月間表'!$A$7:$A$37,0)),""))
A17: 第2週 | B17: =IF(MONTH($B$4-WEEKDAY($B$4)+1+7)<>MONTH($B$4),"",$B$4-WEEKDAY($B$4)+1+7) | C17: =IF(MONTH($B$4-WEEKDAY($B$4)+1+8)<>MONTH($B$4),"",$B$4-WEEKDAY($B$4)+1+8) | D17: =IF(MONTH($B$4-WEEKDAY($B$4)+1+9)<>MONTH($B$4),"",$B$4-WEEKDAY($B$4)+1+9) | E17: =IF(MONTH($B$4-WEEKDAY($B$4)+1+10)<>MONTH($B$4),"",$B$4-WEEKDAY($B$4)+1+10) | F17: =IF(MONTH($B$4-WEEKDAY($B$4)+1+11)<>MONTH($B$4),"",$B$4-WEEKDAY($B$4)+1+11) | G17: =IF(MONTH($B$4-WEEKDAY($B$4)+1+12)<>MONTH($B$4),"",$B$4-WEEKDAY($B$4)+1+12) | H17: =IF(MONTH($B$4-WEEKDAY($B$4)+1+13)<>MONTH($B$4),"",$B$4-WEEKDAY($B$4)+1+13)
A18: =IF(COUNTA('M_部屋'!$A$4:$A$20)>=1,INDEX('M_部屋'!$A$4:$A$20,1),"") | B18: =IF(B17="","",IFERROR(INDEX('04_月間表'!C$7:C$37,MATCH(B17,'04_月間表'!$A$7:$A$37,0)),"")) | C18: =IF(C17="","",IFERROR(INDEX('04_月間表'!C$7:C$37,MATCH(C17,'04_月間表'!$A$7:$A$37,0)),"")) | D18: =IF(D17="","",IFERROR(INDEX('04_月間表'!C$7:C$37,MATCH(D17,'04_月間表'!$A$7:$A$37,0)),"")) | E18: =IF(E17="","",IFERROR(INDEX('04_月間表'!C$7:C$37,MATCH(E17,'04_月間表'!$A$7:$A$37,0)),"")) | F18: =IF(F17="","",IFERROR(INDEX('04_月間表'!C$7:C$37,MATCH(F17,'04_月間表'!$A$7:$A$37,0)),"")) | G18: =IF(G17="","",IFERROR(INDEX('04_月間表'!C$7:C$37,MATCH(G17,'04_月間表'!$A$7:$A$37,0)),"")) | H18: =IF(H17="","",IFERROR(INDEX('04_月間表'!C$7:C$37,MATCH(H17,'04_月間表'!$A$7:$A$37,0)),"")) | J18: =IF(B17="","",IFERROR(INDEX('04_月間表'!X$7:X$37,MATCH(B17,'04_月間表'!$A$7:$A$37,0)),"")) | K18: =IF(C17="","",IFERROR(INDEX('04_月間表'!X$7:X$37,MATCH(C17,'04_月間表'!$A$7:$A$37,0)),"")) | L18: =IF(D17="","",IFERROR(INDEX('04_月間表'!X$7:X$37,MATCH(D17,'04_月間表'!$A$7:$A$37,0)),"")) | M18: =IF(E17="","",IFERROR(INDEX('04_月間表'!X$7:X$37,MATCH(E17,'04_月間表'!$A$7:$A$37,0)),"")) | N18: =IF(F17="","",IFERROR(INDEX('04_月間表'!X$7:X$37,MATCH(F17,'04_月間表'!$A$7:$A$37,0)),"")) | O18: =IF(G17="","",IFERROR(INDEX('04_月間表'!X$7:X$37,MATCH(G17,'04_月間表'!$A$7:$A$37,0)),"")) | P18: =IF(H17="","",IFERROR(INDEX('04_月間表'!X$7:X$37,MATCH(H17,'04_月間表'!$A$7:$A$37,0)),""))
A19: =IF(COUNTA('M_部屋'!$A$4:$A$20)>=2,INDEX('M_部屋'!$A$4:$A$20,2),"") | B19: =IF(B17="","",IFERROR(INDEX('04_月間表'!D$7:D$37,MATCH(B17,'04_月間表'!$A$7:$A$37,0)),"")) | C19: =IF(C17="","",IFERROR(INDEX('04_月間表'!D$7:D$37,MATCH(C17,'04_月間表'!$A$7:$A$37,0)),"")) | D19: =IF(D17="","",IFERROR(INDEX('04_月間表'!D$7:D$37,MATCH(D17,'04_月間表'!$A$7:$A$37,0)),"")) | E19: =IF(E17="","",IFERROR(INDEX('04_月間表'!D$7:D$37,MATCH(E17,'04_月間表'!$A$7:$A$37,0)),"")) | F19: =IF(F17="","",IFERROR(INDEX('04_月間表'!D$7:D$37,MATCH(F17,'04_月間表'!$A$7:$A$37,0)),"")) | G19: =IF(G17="","",IFERROR(INDEX('04_月間表'!D$7:D$37,MATCH(G17,'04_月間表'!$A$7:$A$37,0)),"")) | H19: =IF(H17="","",IFERROR(INDEX('04_月間表'!D$7:D$37,MATCH(H17,'04_月間表'!$A$7:$A$37,0)),"")) | J19: =IF(B17="","",IFERROR(INDEX('04_月間表'!Y$7:Y$37,MATCH(B17,'04_月間表'!$A$7:$A$37,0)),"")) | K19: =IF(C17="","",IFERROR(INDEX('04_月間表'!Y$7:Y$37,MATCH(C17,'04_月間表'!$A$7:$A$37,0)),"")) | L19: =IF(D17="","",IFERROR(INDEX('04_月間表'!Y$7:Y$37,MATCH(D17,'04_月間表'!$A$7:$A$37,0)),"")) | M19: =IF(E17="","",IFERROR(INDEX('04_月間表'!Y$7:Y$37,MATCH(E17,'04_月間表'!$A$7:$A$37,0)),"")) | N19: =IF(F17="","",IFERROR(INDEX('04_月間表'!Y$7:Y$37,MATCH(F17,'04_月間表'!$A$7:$A$37,0)),"")) | O19: =IF(G17="","",IFERROR(INDEX('04_月間表'!Y$7:Y$37,MATCH(G17,'04_月間表'!$A$7:$A$37,0)),"")) | P19: =IF(H17="","",IFERROR(INDEX('04_月間表'!Y$7:Y$37,MATCH(H17,'04_月間表'!$A$7:$A$37,0)),""))
A20: =IF(COUNTA('M_部屋'!$A$4:$A$20)>=3,INDEX('M_部屋'!$A$4:$A$20,3),"") | B20: =IF(B17="","",IFERROR(INDEX('04_月間表'!E$7:E$37,MATCH(B17,'04_月間表'!$A$7:$A$37,0)),"")) | C20: =IF(C17="","",IFERROR(INDEX('04_月間表'!E$7:E$37,MATCH(C17,'04_月間表'!$A$7:$A$37,0)),"")) | D20: =IF(D17="","",IFERROR(INDEX('04_月間表'!E$7:E$37,MATCH(D17,'04_月間表'!$A$7:$A$37,0)),"")) | E20: =IF(E17="","",IFERROR(INDEX('04_月間表'!E$7:E$37,MATCH(E17,'04_月間表'!$A$7:$A$37,0)),"")) | F20: =IF(F17="","",IFERROR(INDEX('04_月間表'!E$7:E$37,MATCH(F17,'04_月間表'!$A$7:$A$37,0)),"")) | G20: =IF(G17="","",IFERROR(INDEX('04_月間表'!E$7:E$37,MATCH(G17,'04_月間表'!$A$7:$A$37,0)),"")) | H20: =IF(H17="","",IFERROR(INDEX('04_月間表'!E$7:E$37,MATCH(H17,'04_月間表'!$A$7:$A$37,0)),"")) | J20: =IF(B17="","",IFERROR(INDEX('04_月間表'!Z$7:Z$37,MATCH(B17,'04_月間表'!$A$7:$A$37,0)),"")) | K20: =IF(C17="","",IFERROR(INDEX('04_月間表'!Z$7:Z$37,MATCH(C17,'04_月間表'!$A$7:$A$37,0)),"")) | L20: =IF(D17="","",IFERROR(INDEX('04_月間表'!Z$7:Z$37,MATCH(D17,'04_月間表'!$A$7:$A$37,0)),"")) | M20: =IF(E17="","",IFERROR(INDEX('04_月間表'!Z$7:Z$37,MATCH(E17,'04_月間表'!$A$7:$A$37,0)),"")) | N20: =IF(F17="","",IFERROR(INDEX('04_月間表'!Z$7:Z$37,MATCH(F17,'04_月間表'!$A$7:$A$37,0)),"")) | O20: =IF(G17="","",IFERROR(INDEX('04_月間表'!Z$7:Z$37,MATCH(G17,'04_月間表'!$A$7:$A$37,0)),"")) | P20: =IF(H17="","",IFERROR(INDEX('04_月間表'!Z$7:Z$37,MATCH(H17,'04_月間表'!$A$7:$A$37,0)),""))
A21: =IF(COUNTA('M_部屋'!$A$4:$A$20)>=4,INDEX('M_部屋'!$A$4:$A$20,4),"") | B21: =IF(B17="","",IFERROR(INDEX('04_月間表'!F$7:F$37,MATCH(B17,'04_月間表'!$A$7:$A$37,0)),"")) | C21: =IF(C17="","",IFERROR(INDEX('04_月間表'!F$7:F$37,MATCH(C17,'04_月間表'!$A$7:$A$37,0)),"")) | D21: =IF(D17="","",IFERROR(INDEX('04_月間表'!F$7:F$37,MATCH(D17,'04_月間表'!$A$7:$A$37,0)),"")) | E21: =IF(E17="","",IFERROR(INDEX('04_月間表'!F$7:F$37,MATCH(E17,'04_月間表'!$A$7:$A$37,0)),"")) | F21: =IF(F17="","",IFERROR(INDEX('04_月間表'!F$7:F$37,MATCH(F17,'04_月間表'!$A$7:$A$37,0)),"")) | G21: =IF(G17="","",IFERROR(INDEX('04_月間表'!F$7:F$37,MATCH(G17,'04_月間表'!$A$7:$A$37,0)),"")) | H21: =IF(H17="","",IFERROR(INDEX('04_月間表'!F$7:F$37,MATCH(H17,'04_月間表'!$A$7:$A$37,0)),"")) | J21: =IF(B17="","",IFERROR(INDEX('04_月間表'!AA$7:AA$37,MATCH(B17,'04_月間表'!$A$7:$A$37,0)),"")) | K21: =IF(C17="","",IFERROR(INDEX('04_月間表'!AA$7:AA$37,MATCH(C17,'04_月間表'!$A$7:$A$37,0)),"")) | L21: =IF(D17="","",IFERROR(INDEX('04_月間表'!AA$7:AA$37,MATCH(D17,'04_月間表'!$A$7:$A$37,0)),"")) | M21: =IF(E17="","",IFERROR(INDEX('04_月間表'!AA$7:AA$37,MATCH(E17,'04_月間表'!$A$7:$A$37,0)),"")) | N21: =IF(F17="","",IFERROR(INDEX('04_月間表'!AA$7:AA$37,MATCH(F17,'04_月間表'!$A$7:$A$37,0)),"")) | O21: =IF(G17="","",IFERROR(INDEX('04_月間表'!AA$7:AA$37,MATCH(G17,'04_月間表'!$A$7:$A$37,0)),"")) | P21: =IF(H17="","",IFERROR(INDEX('04_月間表'!AA$7:AA$37,MATCH(H17,'04_月間表'!$A$7:$A$37,0)),""))
A22: 空き | B22: =IF(B17="","",IFERROR(INDEX('04_月間表'!$J$7:$J$37,MATCH(B17,'04_月間表'!$A$7:$A$37,0)),"")) | C22: =IF(C17="","",IFERROR(INDEX('04_月間表'!$J$7:$J$37,MATCH(C17,'04_月間表'!$A$7:$A$37,0)),"")) | D22: =IF(D17="","",IFERROR(INDEX('04_月間表'!$J$7:$J$37,MATCH(D17,'04_月間表'!$A$7:$A$37,0)),"")) | E22: =IF(E17="","",IFERROR(INDEX('04_月間表'!$J$7:$J$37,MATCH(E17,'04_月間表'!$A$7:$A$37,0)),"")) | F22: =IF(F17="","",IFERROR(INDEX('04_月間表'!$J$7:$J$37,MATCH(F17,'04_月間表'!$A$7:$A$37,0)),"")) | G22: =IF(G17="","",IFERROR(INDEX('04_月間表'!$J$7:$J$37,MATCH(G17,'04_月間表'!$A$7:$A$37,0)),"")) | H22: =IF(H17="","",IFERROR(INDEX('04_月間表'!$J$7:$J$37,MATCH(H17,'04_月間表'!$A$7:$A$37,0)),""))
A23: 食事 | B23: =IF(OR(B17="",$B$6<>"○"),"",IFERROR(INDEX('04_月間表'!$AI$7:$AI$37,MATCH(B17,'04_月間表'!$A$7:$A$37,0)),"")) | C23: =IF(OR(C17="",$B$6<>"○"),"",IFERROR(INDEX('04_月間表'!$AI$7:$AI$37,MATCH(C17,'04_月間表'!$A$7:$A$37,0)),"")) | D23: =IF(OR(D17="",$B$6<>"○"),"",IFERROR(INDEX('04_月間表'!$AI$7:$AI$37,MATCH(D17,'04_月間表'!$A$7:$A$37,0)),"")) | E23: =IF(OR(E17="",$B$6<>"○"),"",IFERROR(INDEX('04_月間表'!$AI$7:$AI$37,MATCH(E17,'04_月間表'!$A$7:$A$37,0)),"")) | F23: =IF(OR(F17="",$B$6<>"○"),"",IFERROR(INDEX('04_月間表'!$AI$7:$AI$37,MATCH(F17,'04_月間表'!$A$7:$A$37,0)),"")) | G23: =IF(OR(G17="",$B$6<>"○"),"",IFERROR(INDEX('04_月間表'!$AI$7:$AI$37,MATCH(G17,'04_月間表'!$A$7:$A$37,0)),"")) | H23: =IF(OR(H17="",$B$6<>"○"),"",IFERROR(INDEX('04_月間表'!$AI$7:$AI$37,MATCH(H17,'04_月間表'!$A$7:$A$37,0)),""))
A25: 第3週 | B25: =IF(MONTH($B$4-WEEKDAY($B$4)+1+14)<>MONTH($B$4),"",$B$4-WEEKDAY($B$4)+1+14) | C25: =IF(MONTH($B$4-WEEKDAY($B$4)+1+15)<>MONTH($B$4),"",$B$4-WEEKDAY($B$4)+1+15) | D25: =IF(MONTH($B$4-WEEKDAY($B$4)+1+16)<>MONTH($B$4),"",$B$4-WEEKDAY($B$4)+1+16) | E25: =IF(MONTH($B$4-WEEKDAY($B$4)+1+17)<>MONTH($B$4),"",$B$4-WEEKDAY($B$4)+1+17) | F25: =IF(MONTH($B$4-WEEKDAY($B$4)+1+18)<>MONTH($B$4),"",$B$4-WEEKDAY($B$4)+1+18) | G25: =IF(MONTH($B$4-WEEKDAY($B$4)+1+19)<>MONTH($B$4),"",$B$4-WEEKDAY($B$4)+1+19) | H25: =IF(MONTH($B$4-WEEKDAY($B$4)+1+20)<>MONTH($B$4),"",$B$4-WEEKDAY($B$4)+1+20)
A26: =IF(COUNTA('M_部屋'!$A$4:$A$20)>=1,INDEX('M_部屋'!$A$4:$A$20,1),"") | B26: =IF(B25="","",IFERROR(INDEX('04_月間表'!C$7:C$37,MATCH(B25,'04_月間表'!$A$7:$A$37,0)),"")) | C26: =IF(C25="","",IFERROR(INDEX('04_月間表'!C$7:C$37,MATCH(C25,'04_月間表'!$A$7:$A$37,0)),"")) | D26: =IF(D25="","",IFERROR(INDEX('04_月間表'!C$7:C$37,MATCH(D25,'04_月間表'!$A$7:$A$37,0)),"")) | E26: =IF(E25="","",IFERROR(INDEX('04_月間表'!C$7:C$37,MATCH(E25,'04_月間表'!$A$7:$A$37,0)),"")) | F26: =IF(F25="","",IFERROR(INDEX('04_月間表'!C$7:C$37,MATCH(F25,'04_月間表'!$A$7:$A$37,0)),"")) | G26: =IF(G25="","",IFERROR(INDEX('04_月間表'!C$7:C$37,MATCH(G25,'04_月間表'!$A$7:$A$37,0)),"")) | H26: =IF(H25="","",IFERROR(INDEX('04_月間表'!C$7:C$37,MATCH(H25,'04_月間表'!$A$7:$A$37,0)),"")) | J26: =IF(B25="","",IFERROR(INDEX('04_月間表'!X$7:X$37,MATCH(B25,'04_月間表'!$A$7:$A$37,0)),"")) | K26: =IF(C25="","",IFERROR(INDEX('04_月間表'!X$7:X$37,MATCH(C25,'04_月間表'!$A$7:$A$37,0)),"")) | L26: =IF(D25="","",IFERROR(INDEX('04_月間表'!X$7:X$37,MATCH(D25,'04_月間表'!$A$7:$A$37,0)),"")) | M26: =IF(E25="","",IFERROR(INDEX('04_月間表'!X$7:X$37,MATCH(E25,'04_月間表'!$A$7:$A$37,0)),"")) | N26: =IF(F25="","",IFERROR(INDEX('04_月間表'!X$7:X$37,MATCH(F25,'04_月間表'!$A$7:$A$37,0)),"")) | O26: =IF(G25="","",IFERROR(INDEX('04_月間表'!X$7:X$37,MATCH(G25,'04_月間表'!$A$7:$A$37,0)),"")) | P26: =IF(H25="","",IFERROR(INDEX('04_月間表'!X$7:X$37,MATCH(H25,'04_月間表'!$A$7:$A$37,0)),""))
A27: =IF(COUNTA('M_部屋'!$A$4:$A$20)>=2,INDEX('M_部屋'!$A$4:$A$20,2),"") | B27: =IF(B25="","",IFERROR(INDEX('04_月間表'!D$7:D$37,MATCH(B25,'04_月間表'!$A$7:$A$37,0)),"")) | C27: =IF(C25="","",IFERROR(INDEX('04_月間表'!D$7:D$37,MATCH(C25,'04_月間表'!$A$7:$A$37,0)),"")) | D27: =IF(D25="","",IFERROR(INDEX('04_月間表'!D$7:D$37,MATCH(D25,'04_月間表'!$A$7:$A$37,0)),"")) | E27: =IF(E25="","",IFERROR(INDEX('04_月間表'!D$7:D$37,MATCH(E25,'04_月間表'!$A$7:$A$37,0)),"")) | F27: =IF(F25="","",IFERROR(INDEX('04_月間表'!D$7:D$37,MATCH(F25,'04_月間表'!$A$7:$A$37,0)),"")) | G27: =IF(G25="","",IFERROR(INDEX('04_月間表'!D$7:D$37,MATCH(G25,'04_月間表'!$A$7:$A$37,0)),"")) | H27: =IF(H25="","",IFERROR(INDEX('04_月間表'!D$7:D$37,MATCH(H25,'04_月間表'!$A$7:$A$37,0)),"")) | J27: =IF(B25="","",IFERROR(INDEX('04_月間表'!Y$7:Y$37,MATCH(B25,'04_月間表'!$A$7:$A$37,0)),"")) | K27: =IF(C25="","",IFERROR(INDEX('04_月間表'!Y$7:Y$37,MATCH(C25,'04_月間表'!$A$7:$A$37,0)),"")) | L27: =IF(D25="","",IFERROR(INDEX('04_月間表'!Y$7:Y$37,MATCH(D25,'04_月間表'!$A$7:$A$37,0)),"")) | M27: =IF(E25="","",IFERROR(INDEX('04_月間表'!Y$7:Y$37,MATCH(E25,'04_月間表'!$A$7:$A$37,0)),"")) | N27: =IF(F25="","",IFERROR(INDEX('04_月間表'!Y$7:Y$37,MATCH(F25,'04_月間表'!$A$7:$A$37,0)),"")) | O27: =IF(G25="","",IFERROR(INDEX('04_月間表'!Y$7:Y$37,MATCH(G25,'04_月間表'!$A$7:$A$37,0)),"")) | P27: =IF(H25="","",IFERROR(INDEX('04_月間表'!Y$7:Y$37,MATCH(H25,'04_月間表'!$A$7:$A$37,0)),""))
A28: =IF(COUNTA('M_部屋'!$A$4:$A$20)>=3,INDEX('M_部屋'!$A$4:$A$20,3),"") | B28: =IF(B25="","",IFERROR(INDEX('04_月間表'!E$7:E$37,MATCH(B25,'04_月間表'!$A$7:$A$37,0)),"")) | C28: =IF(C25="","",IFERROR(INDEX('04_月間表'!E$7:E$37,MATCH(C25,'04_月間表'!$A$7:$A$37,0)),"")) | D28: =IF(D25="","",IFERROR(INDEX('04_月間表'!E$7:E$37,MATCH(D25,'04_月間表'!$A$7:$A$37,0)),"")) | E28: =IF(E25="","",IFERROR(INDEX('04_月間表'!E$7:E$37,MATCH(E25,'04_月間表'!$A$7:$A$37,0)),"")) | F28: =IF(F25="","",IFERROR(INDEX('04_月間表'!E$7:E$37,MATCH(F25,'04_月間表'!$A$7:$A$37,0)),"")) | G28: =IF(G25="","",IFERROR(INDEX('04_月間表'!E$7:E$37,MATCH(G25,'04_月間表'!$A$7:$A$37,0)),"")) | H28: =IF(H25="","",IFERROR(INDEX('04_月間表'!E$7:E$37,MATCH(H25,'04_月間表'!$A$7:$A$37,0)),"")) | J28: =IF(B25="","",IFERROR(INDEX('04_月間表'!Z$7:Z$37,MATCH(B25,'04_月間表'!$A$7:$A$37,0)),"")) | K28: =IF(C25="","",IFERROR(INDEX('04_月間表'!Z$7:Z$37,MATCH(C25,'04_月間表'!$A$7:$A$37,0)),"")) | L28: =IF(D25="","",IFERROR(INDEX('04_月間表'!Z$7:Z$37,MATCH(D25,'04_月間表'!$A$7:$A$37,0)),"")) | M28: =IF(E25="","",IFERROR(INDEX('04_月間表'!Z$7:Z$37,MATCH(E25,'04_月間表'!$A$7:$A$37,0)),"")) | N28: =IF(F25="","",IFERROR(INDEX('04_月間表'!Z$7:Z$37,MATCH(F25,'04_月間表'!$A$7:$A$37,0)),"")) | O28: =IF(G25="","",IFERROR(INDEX('04_月間表'!Z$7:Z$37,MATCH(G25,'04_月間表'!$A$7:$A$37,0)),"")) | P28: =IF(H25="","",IFERROR(INDEX('04_月間表'!Z$7:Z$37,MATCH(H25,'04_月間表'!$A$7:$A$37,0)),""))
